Workbook

Sheet Ringkasan
A1: Kode | B1: Nama Perusahaan | C1: Penutupan | D1: =IFERROR(__xludf.DUMMYFUNCTION("""Last Update: "" & TEXT(NOW() - GOOGLEFINANCE(""IDX:BBCA"",""datadelay"")/1440, ""dddd, yyyymmdd HH:mm"")"),"Last Update: Minggu, 20260614 14:19") -> Last Update: Minggu, 20260614 14:19 | E1: Index | F1: Index Expired | G1: ∑i ≥ 7 | H1: PER | I1: PBV | J1: ROE | K1: ROA | L1: DER | M1: NPM | N1: NIM | O1: CAR | P1: LDR | Q1: NPL | R1: BOPO | S1: CIR | T1: LAR | U1: Sebelumnya | V1: %Change | W1: Open | X1: High | Y1: Low | Z1: Volume | AA1: Industry | AB1: Sektor
A2: AADI | B2: {=VLOOKUP(A2,{Metrik!$C$2:$C$998,Metrik!$B$2:$B$998},2,0)} -> Adaro Andalan Indonesia Tbk. | C2: =IFERROR(__xludf.DUMMYFUNCTION("GOOGLEFINANCE(""IDX:""&A2,""price"")"),8650.0) -> 8650 | D2: =IFERROR(__xludf.DUMMYFUNCTION("IF(A2="""","""", SPARKLINE( INDEX( GOOGLEFINANCE(""IDX:""&A2,""close"",TODAY()-365,TODAY()), ,2 ), {""linewidth"",1} )) "),"#N/A") -> #N/A | E2: IDX80 | F2: 31 Juli 2026 | G2: =COUNTIFS($B$2:$B$1937,B2,$E$2:$E$1937,"<>") -> 9 | H2: =VLOOKUP(A2,Metrik!$C$2:$Y$959,8,0) -> 5.5 | I2: =VLOOKUP(A2,Metrik!$C$2:$Y$959,9,0) -> 1 | J2: =VLOOKUP(A2,Metrik!$C$2:$Y$959,10,0) -> 18.6 | K2: =VLOOKUP(A2,Metrik!$C$2:$Y$959,11,0) -> 12.2 | L2: =VLOOKUP(A2,Metrik!$C$2:$Y$959,12,0) -> 0.53 | M2: =VLOOKUP(A2,Metrik!$C$2:$Y$959,19,0) -> 67.3 | U2: =IFERROR(__xludf.DUMMYFUNCTION("IFERROR(GOOGLEFINANCE(A2,""closeyest""),"""")"),8050.0) -> 8050 | V2: =IFERROR(__xludf.DUMMYFUNCTION("IFERROR(GOOGLEFINANCE(A2,""changepct""),"""")"),7.45) -> 7.45 | W2: =IFERROR(__xludf.DUMMYFUNCTION("IFERROR(GOOGLEFINANCE(A2,""priceopen""),"""")"),8100.0) -> 8100 | X2: =IFERROR(__xludf.DUMMYFUNCTION("IFERROR(GOOGLEFINANCE(A2,""high""),"""")"),8850.0) -> 8850 | Y2: =IFERROR(__xludf.DUMMYFUNCTION("IFERROR(GOOGLEFINANCE(A2,""low""),"""")"),8050.0) -> 8050 | Z2: =IFERROR(__xludf.DUMMYFUNCTION("IFERROR(GOOGLEFINANCE(A2,""volume""),"""")"),2.12622E7) -> 21262200 | AA2: =VLOOKUP(A2,Metrik!$C$2:$Y$959,5,0) -> Coal | AB2: =VLOOKUP(A2,Metrik!$C$2:$Y$959,3,0) -> Energy
A3: AADI | B3: {=VLOOKUP(A3,{Metrik!$C$2:$C$998,Metrik!$B$2:$B$998},2,0)} -> Adaro Andalan Indonesia Tbk. | C3: =IFERROR(__xludf.DUMMYFUNCTION("GOOGLEFINANCE(""IDX:""&A3,""price"")"),8650.0) -> 8650 | D3: =IFERROR(__xludf.DUMMYFUNCTION("IF(A3="""","""", SPARKLINE( INDEX( GOOGLEFINANCE(""IDX:""&A3,""close"",TODAY()-365,TODAY()), ,2 ), {""linewidth"",1} )) "),"#N/A") -> #N/A | E3: IDX30 | F3: 31 Juli 2026 | G3: =COUNTIFS($B$2:$B$1937,B3,$E$2:$E$1937,"<>") -> 9 | H3: =VLOOKUP(A3,Metrik!$C$2:$Y$959,8,0) -> 5.5 | I3: =VLOOKUP(A3,Metrik!$C$2:$Y$959,9,0) -> 1 | J3: =VLOOKUP(A3,Metrik!$C$2:$Y$959,10,0) -> 18.6 | K3: =VLOOKUP(A3,Metrik!$C$2:$Y$959,11,0) -> 12.2 | L3: =VLOOKUP(A3,Metrik!$C$2:$Y$959,12,0) -> 0.53 | M3: =VLOOKUP(A3,Metrik!$C$2:$Y$959,19,0) -> 67.3 | U3: =IFERROR(__xludf.DUMMYFUNCTION("IFERROR(GOOGLEFINANCE(A3,""closeyest""),"""")"),8050.0) -> 8050 | V3: =IFERROR(__xludf.DUMMYFUNCTION("IFERROR(GOOGLEFINANCE(A3,""changepct""),"""")"),7.45) -> 7.45 | W3: =IFERROR(__xludf.DUMMYFUNCTION("IFERROR(GOOGLEFINANCE(A3,""priceopen""),"""")"),8100.0) -> 8100 | X3: =IFERROR(__xludf.DUMMYFUNCTION("IFERROR(GOOGLEFINANCE(A3,""high""),"""")"),8850.0) -> 8850 | Y3: =IFERROR(__xludf.DUMMYFUNCTION("IFERROR(GOOGLEFINANCE(A3,""low""),"""")"),8050.0) -> 8050 | Z3: =IFERROR(__xludf.DUMMYFUNCTION("IFERROR(GOOGLEFINANCE(A3,""volume""),"""")"),2.12622E7) -> 21262200 | AA3: =VLOOKUP(A3,Metrik!$C$2:$Y$959,5,0) -> Coal | AB3: =VLOOKUP(A3,Metrik!$C$2:$Y$959,3,0) -> Energy
A4: AADI | B4: {=VLOOKUP(A4,{Metrik!$C$2:$C$998,Metrik!$B$2:$B$998},2,0)} -> Adaro Andalan Indonesia Tbk. | C4: =IFERROR(__xludf.DUMMYFUNCTION("GOOGLEFINANCE(""IDX:""&A4,""price"")"),8650.0) -> 8650 | D4: =IFERROR(__xludf.DUMMYFUNCTION("IF(A4="""","""", SPARKLINE( INDEX( GOOGLEFINANCE(""IDX:""&A4,""close"",TODAY()-365,TODAY()), ,2 ), {""linewidth"",1} )) "),"#N/A") -> #N/A | E4: LQ45 | F4: 31 Juli 2026 | G4: =COUNTIFS($B$2:$B$1937,B4,$E$2:$E$1937,"<>") -> 9 | H4: =VLOOKUP(A4,Metrik!$C$2:$Y$959,8,0) -> 5.5 | I4: =VLOOKUP(A4,Metrik!$C$2:$Y$959,9,0) -> 1 | J4: =VLOOKUP(A4,Metrik!$C$2:$Y$959,10,0) -> 18.6 | K4: =VLOOKUP(A4,Metrik!$C$2:$Y$959,11,0) -> 12.2 | L4: =VLOOKUP(A4,Metrik!$C$2:$Y$959,12,0) -> 0.53 | M4: =VLOOKUP(A4,Metrik!$C$2:$Y$959,19,0) -> 67.3 | U4: =IFERROR(__xludf.DUMMYFUNCTION("IFERROR(GOOGLEFINANCE(A4,""closeyest""),"""")"),8050.0) -> 8050 | V4: =IFERROR(__xludf.DUMMYFUNCTION("IFERROR(GOOGLEFINANCE(A4,""changepct""),"""")"),7.45) -> 7.45 | W4: =IFERROR(__xludf.DUMMYFUNCTION("IFERROR(GOOGLEFINANCE(A4,""priceopen""),"""")"),8100.0) -> 8100 | X4: =IFERROR(__xludf.DUMMYFUNCTION("IFERROR(GOOGLEFINANCE(A4,""high""),"""")"),8850.0) -> 8850 | Y4: =IFERROR(__xludf.DUMMYFUNCTION("IFERROR(GOOGLEFINANCE(A4,""low""),"""")"),8050.0) -> 8050 | Z4: =IFERROR(__xludf.DUMMYFUNCTION("IFERROR(GOOGLEFINANCE(A4,""volume""),"""")"),2.12622E7) -> 21262200 | AA4: =VLOOKUP(A4,Metrik!$C$2:$Y$959,5,0) -> Coal | AB4: =VLOOKUP(A4,Metrik!$C$2:$Y$959,3,0) -> Energy
A5: AADI | B5: {=VLOOKUP(A5,{Metrik!$C$2:$C$998,Metrik!$B$2:$B$998},2,0)} -> Adaro Andalan Indonesia Tbk. | C5: =IFERROR(__xludf.DUMMYFUNCTION("GOOGLEFINANCE(""IDX:""&A5,""price"")"),8650.0) -> 8650 | D5: =IFERROR(__xludf.DUMMYFUNCTION("IF(A5="""","""", SPARKLINE( INDEX( GOOGLEFINANCE(""IDX:""&A5,""close"",TODAY()-365,TODAY()), ,2 ), {""linewidth"",1} )) "),"#N/A") -> #N/A | E5: Kompas100 | F5: 31 Juli 2026 | G5: =COUNTIFS($B$2:$B$1937,B5,$E$2:$E$1937,"<>") -> 9 | H5: =VLOOKUP(A5,Metrik!$C$2:$Y$959,8,0) -> 5.5 | I5: =VLOOKUP(A5,Metrik!$C$2:$Y$959,9,0) -> 1 | J5: =VLOOKUP(A5,Metrik!$C$2:$Y$959,10,0) -> 18.6 | K5: =VLOOKUP(A5,Metrik!$C$2:$Y$959,11,0) -> 12.2 | L5: =VLOOKUP(A5,Metrik!$C$2:$Y$959,12,0) -> 0.53 | M5: =VLOOKUP(A5,Metrik!$C$2:$Y$959,19,0) -> 67.3 | U5: =IFERROR(__xludf.DUMMYFUNCTION("IFERROR(GOOGLEFINANCE(A5,""closeyest""),"""")"),8050.0) -> 8050 | V5: =IFERROR(__xludf.DUMMYFUNCTION("IFERROR(GOOGLEFINANCE(A5,""changepct""),"""")"),7.45) -> 7.45 | W5: =IFERROR(__xludf.DUMMYFUNCTION("IFERROR(GOOGLEFINANCE(A5,""priceopen""),"""")"),8100.0) -> 8100 | X5: =IFERROR(__xludf.DUMMYFUNCTION("IFERROR(GOOGLEFINANCE(A5,""high""),"""")"),8850.0) -> 8850 | Y5: =IFERROR(__xludf.DUMMYFUNCTION("IFERROR(GOOGLEFINANCE(A5,""low""),"""")"),8050.0) -> 8050 | Z5: =IFERROR(__xludf.DUMMYFUNCTION("IFERROR(GOOGLEFINANCE(A5,""volume""),"""")"),2.12622E7) -> 21262200 | AA5: =VLOOKUP(A5,Metrik!$C$2:$Y$959,5,0) -> Coal | AB5: =VLOOKUP(A5,Metrik!$C$2:$Y$959,3,0) -> Energy
A6: AADI | B6: {=VLOOKUP(A6,{Metrik!$C$2:$C$998,Metrik!$B$2:$B$998},2,0)} -> Adaro Andalan Indonesia Tbk. | C6: =IFERROR(__xludf.DUMMYFUNCTION("GOOGLEFINANCE(""IDX:""&A6,""price"")"),8650.0) -> 8650 | D6: =IFERROR(__xludf.DUMMYFUNCTION("IF(A6="""","""", SPARKLINE( INDEX( GOOGLEFINANCE(""IDX:""&A6,""close"",TODAY()-365,TODAY()), ,2 ), {""linewidth"",1} )) "),"#N/A") -> #N/A | E6: IDXV30 | F6: 4 Agustus 2026 | G6: =COUNTIFS($B$2:$B$1937,B6,$E$2:$E$1937,"<>") -> 9 | H6: =VLOOKUP(A6,Metrik!$C$2:$Y$959,8,0) -> 5.5 | I6: =VLOOKUP(A6,Metrik!$C$2:$Y$959,9,0) -> 1 | J6: =VLOOKUP(A6,Metrik!$C$2:$Y$959,10,0) -> 18.6 | K6: =VLOOKUP(A6,Metrik!$C$2:$Y$959,11,0) -> 12.2 | L6: =VLOOKUP(A6,Metrik!$C$2:$Y$959,12,0) -> 0.53 | M6: =VLOOKUP(A6,Metrik!$C$2:$Y$959,19,0) -> 67.3 | U6: =IFERROR(__xludf.DUMMYFUNCTION("IFERROR(GOOGLEFINANCE(A6,""closeyest""),"""")"),8050.0) -> 8050 | V6: =IFERROR(__xludf.DUMMYFUNCTION("IFERROR(GOOGLEFINANCE(A6,""changepct""),"""")"),7.45) -> 7.45 | W6: =IFERROR(__xludf.DUMMYFUNCTION("IFERROR(GOOGLEFINANCE(A6,""priceopen""),"""")"),8100.0) -> 8100 | X6: =IFERROR(__xludf.DUMMYFUNCTION("IFERROR(GOOGLEFINANCE(A6,""high""),"""")"),8850.0) -> 8850 | Y6: =IFERROR(__xludf.DUMMYFUNCTION("IFERROR(GOOGLEFINANCE(A6,""low""),"""")"),8050.0) -> 8050 | Z6: =IFERROR(__xludf.DUMMYFUNCTION("IFERROR(GOOGLEFINANCE(A6,""volume""),"""")"),2.12622E7) -> 21262200 | AA6: =VLOOKUP(A6,Metrik!$C$2:$Y$959,5,0) -> Coal | AB6: =VLOOKUP(A6,Metrik!$C$2:$Y$959,3,0) -> Energy
A7: AADI | B7: {=VLOOKUP(A7,{Metrik!$C$2:$C$998,Metrik!$B$2:$B$998},2,0)} -> Adaro Andalan Indonesia Tbk. | C7: =IFERROR(__xludf.DUMMYFUNCTION("GOOGLEFINANCE(""IDX:""&A7,""price"")"),8650.0) -> 8650 | D7: =IFERROR(__xludf.DUMMYFUNCTION("IF(A7="""","""", SPARKLINE( INDEX( GOOGLEFINANCE(""IDX:""&A7,""close"",TODAY()-365,TODAY()), ,2 ), {""linewidth"",1} )) "),"#N/A") -> #N/A | E7: MSCI Small Cap | F7: 12 Agustus 2026 | G7: =COUNTIFS($B$2:$B$1937,B7,$E$2:$E$1937,"<>") -> 9 | H7: =VLOOKUP(A7,Metrik!$C$2:$Y$959,8,0) -> 5.5 | I7: =VLOOKUP(A7,Metrik!$C$2:$Y$959,9,0) -> 1 | J7: =VLOOKUP(A7,Metrik!$C$2:$Y$959,10,0) -> 18.6 | K7: =VLOOKUP(A7,Metrik!$C$2:$Y$959,11,0) -> 12.2 | L7: =VLOOKUP(A7,Metrik!$C$2:$Y$959,12,0) -> 0.53 | M7: =VLOOKUP(A7,Metrik!$C$2:$Y$959,19,0) -> 67.3 | U7: =IFERROR(__xludf.DUMMYFUNCTION("IFERROR(GOOGLEFINANCE(A7,""closeyest""),"""")"),8050.0) -> 8050 | V7: =IFERROR(__xludf.DUMMYFUNCTION("IFERROR(GOOGLEFINANCE(A7,""changepct""),"""")"),7.45) -> 7.45 | W7: =IFERROR(__xludf.DUMMYFUNCTION("IFERROR(GOOGLEFINANCE(A7,""priceopen""),"""")"),8100.0) -> 8100 | X7: =IFERROR(__xludf.DUMMYFUNCTION("IFERROR(GOOGLEFINANCE(A7,""high""),"""")"),8850.0) -> 8850 | Y7: =IFERROR(__xludf.DUMMYFUNCTION("IFERROR(GOOGLEFINANCE(A7,""low""),"""")"),8050.0) -> 8050 | Z7: =IFERROR(__xludf.DUMMYFUNCTION("IFERROR(GOOGLEFINANCE(A7,""volume""),"""")"),2.12622E7) -> 21262200 | AA7: =VLOOKUP(A7,Metrik!$C$2:$Y$959,5,0) -> Coal | AB7: =VLOOKUP(A7,Metrik!$C$2:$Y$959,3,0) -> Energy
A8: AADI | B8: {=VLOOKUP(A8,{Metrik!$C$2:$C$998,Metrik!$B$2:$B$998},2,0)} -> Adaro Andalan Indonesia Tbk. | C8: =IFERROR(__xludf.DUMMYFUNCTION("GOOGLEFINANCE(""IDX:""&A8,""price"")"),8650.0) -> 8650 | D8: =IFERROR(__xludf.DUMMYFUNCTION("IF(A8="""","""", SPARKLINE( INDEX( GOOGLEFINANCE(""IDX:""&A8,""close"",TODAY()-365,TODAY()), ,2 ), {""linewidth"",1} )) "),"#N/A") -> #N/A | E8: FTSE Small Cap | F8: 12 Agustus 2026 | G8: =COUNTIFS($B$2:$B$1937,B8,$E$2:$E$1937,"<>") -> 9 | H8: =VLOOKUP(A8,Metrik!$C$2:$Y$959,8,0) -> 5.5 | I8: =VLOOKUP(A8,Metrik!$C$2:$Y$959,9,0) -> 1 | J8: =VLOOKUP(A8,Metrik!$C$2:$Y$959,10,0) -> 18.6 | K8: =VLOOKUP(A8,Metrik!$C$2:$Y$959,11,0) -> 12.2 | L8: =VLOOKUP(A8,Metrik!$C$2:$Y$959,12,0) -> 0.53 | M8: =VLOOKUP(A8,Metrik!$C$2:$Y$959,19,0) -> 67.3 | U8: =IFERROR(__xludf.DUMMYFUNCTION("IFERROR(GOOGLEFINANCE(A8,""closeyest""),"""")"),8050.0) -> 8050 | V8: =IFERROR(__xludf.DUMMYFUNCTION("IFERROR(GOOGLEFINANCE(A8,""changepct""),"""")"),7.45) -> 7.45 | W8: =IFERROR(__xludf.DUMMYFUNCTION("IFERROR(GOOGLEFINANCE(A8,""priceopen""),"""")"),8100.0) -> 8100 | X8: =IFERROR(__xludf.DUMMYFUNCTION("IFERROR(GOOGLEFINANCE(A8,""high""),"""")"),8850.0) -> 8850 | Y8: =IFERROR(__xludf.DUMMYFUNCTION("IFERROR(GOOGLEFINANCE(A8,""low""),"""")"),8050.0) -> 8050 | Z8: =IFERROR(__xludf.DUMMYFUNCTION("IFERROR(GOOGLEFINANCE(A8,""volume""),"""")"),2.12622E7) -> 21262200 | AA8: =VLOOKUP(A8,Metrik!$C$2:$Y$959,5,0) -> Coal | AB8: =VLOOKUP(A8,Metrik!$C$2:$Y$959,3,0) -> Energy
A9: AADI | B9: {=VLOOKUP(A9,{Metrik!$C$2:$C$998,Metrik!$B$2:$B$998},2,0)} -> Adaro Andalan Indonesia Tbk. | C9: =IFERROR(__xludf.DUMMYFUNCTION("GOOGLEFINANCE(""IDX:""&A9,""price"")"),8650.0) -> 8650 | D9: =IFERROR(__xludf.DUMMYFUNCTION("IF(A9="""","""", SPARKLINE( INDEX( GOOGLEFINANCE(""IDX:""&A9,""close"",TODAY()-365,TODAY()), ,2 ), {""linewidth"",1} )) "),"#N/A") -> #N/A | E9: JII30 | F9: 46356 | G9: =COUNTIFS($B$2:$B$1937,B9,$E$2:$E$1937,"<>") -> 9 | H9: =VLOOKUP(A9,Metrik!$C$2:$Y$959,8,0) -> 5.5 | I9: =VLOOKUP(A9,Metrik!$C$2:$Y$959,9,0) -> 1 | J9: =VLOOKUP(A9,Metrik!$C$2:$Y$959,10,0) -> 18.6 | K9: =VLOOKUP(A9,Metrik!$C$2:$Y$959,11,0) -> 12.2 | L9: =VLOOKUP(A9,Metrik!$C$2:$Y$959,12,0) -> 0.53 | M9: =VLOOKUP(A9,Metrik!$C$2:$Y$959,19,0) -> 67.3 | U9: =IFERROR(__xludf.DUMMYFUNCTION("IFERROR(GOOGLEFINANCE(A9,""closeyest""),"""")"),8050.0) -> 8050 | V9: =IFERROR(__xludf.DUMMYFUNCTION("IFERROR(GOOGLEFINANCE(A9,""changepct""),"""")"),7.45) -> 7.45 | W9: =IFERROR(__xludf.DUMMYFUNCTION("IFERROR(GOOGLEFINANCE(A9,""priceopen""),"""")"),8100.0) -> 8100 | X9: =IFERROR(__xludf.DUMMYFUNCTION("IFERROR(GOOGLEFINANCE(A9,""high""),"""")"),8850.0) -> 8850 | Y9: =IFERROR(__xludf.DUMMYFUNCTION("IFERROR(GOOGLEFINANCE(A9,""low""),"""")"),8050.0) -> 8050 | Z9: =IFERROR(__xludf.DUMMYFUNCTION("IFERROR(GOOGLEFINANCE(A9,""volume""),"""")"),2.12622E7) -> 21262200 | AA9: =VLOOKUP(A9,Metrik!$C$2:$Y$959,5,0) -> Coal | AB9: =VLOOKUP(A9,Metrik!$C$2:$Y$959,3,0) -> Energy
A10: AADI | B10: {=VLOOKUP(A10,{Metrik!$C$2:$C$998,Metrik!$B$2:$B$998},2,0)} -> Adaro Andalan Indonesia Tbk. | C10: =IFERROR(__xludf.DUMMYFUNCTION("GOOGLEFINANCE(""IDX:""&A10,""price"")"),8650.0) -> 8650 | D10: =IFERROR(__xludf.DUMMYFUNCTION("IF(A10="""","""", SPARKLINE( INDEX( GOOGLEFINANCE(""IDX:""&A10,""close"",TODAY()-365,TODAY()), ,2 ), {""linewidth"",1} )) "),"#N/A") -> #N/A | E10: JII70 | F10: 46356 | G10: =COUNTIFS($B$2:$B$1937,B10,$E$2:$E$1937,"<>") -> 9 | H10: =VLOOKUP(A10,Metrik!$C$2:$Y$959,8,0) -> 5.5 | I10: =VLOOKUP(A10,Metrik!$C$2:$Y$959,9,0) -> 1 | J10: =VLOOKUP(A10,Metrik!$C$2:$Y$959,10,0) -> 18.6 | K10: =VLOOKUP(A10,Metrik!$C$2:$Y$959,11,0) -> 12.2 | L10: =VLOOKUP(A10,Metrik!$C$2:$Y$959,12,0) -> 0.53 | M10: =VLOOKUP(A10,Metrik!$C$2:$Y$959,19,0) -> 67.3 | U10: =IFERROR(__xludf.DUMMYFUNCTION("IFERROR(GOOGLEFINANCE(A10,""closeyest""),"""")"),8050.0) -> 8050 | V10: =IFERROR(__xludf.DUMMYFUNCTION("IFERROR(GOOGLEFINANCE(A10,""changepct""),"""")"),7.45) -> 7.45 | W10: =IFERROR(__xludf.DUMMYFUNCTION("IFERROR(GOOGLEFINANCE(A10,""priceopen""),"""")"),8100.0) -> 8100 | X10: =IFERROR(__xludf.DUMMYFUNCTION("IFERROR(GOOGLEFINANCE(A10,""high""),"""")"),8850.0) -> 8850 | Y10: =IFERROR(__xludf.DUMMYFUNCTION("IFERROR(GOOGLEFINANCE(A10,""low""),"""")"),8050.0) -> 8050 | Z10: =IFERROR(__xludf.DUMMYFUNCTION("IFERROR(GOOGLEFINANCE(A10,""volume""),"""")"),2.12622E7) -> 21262200 | AA10: =VLOOKUP(A10,Metrik!$C$2:$Y$959,5,0) -> Coal | AB10: =VLOOKUP(A10,Metrik!$C$2:$Y$959,3,0) -> Energy
A11: AALI | B11: {=VLOOKUP(A11,{Metrik!$C$2:$C$998,Metrik!$B$2:$B$998},2,0)} -> Astra Agro Lestari Tbk | C11: =IFERROR(__xludf.DUMMYFUNCTION("GOOGLEFINANCE(""IDX:""&A11,""price"")"),6175.0) -> 6175 | D11: =IFERROR(__xludf.DUMMYFUNCTION("IF(A11="""","""", SPARKLINE( INDEX( GOOGLEFINANCE(""IDX:""&A11,""close"",TODAY()-365,TODAY()), ,2 ), {""linewidth"",1} )) "),"#N/A") -> #N/A | E11: IDXSMC-LIQ | F11: 4 Agustus 2026 | G11: =COUNTIFS($B$2:$B$1937,B11,$E$2:$E$1937,"<>") -> 2 | H11: =VLOOKUP(A11,Metrik!$C$2:$Y$959,8,0) -> 8 | I11: =VLOOKUP(A11,Metrik!$C$2:$Y$959,9,0) -> 0.51 | J11: =VLOOKUP(A11,Metrik!$C$2:$Y$959,10,0) -> 6.4 | K11: =VLOOKUP(A11,Metrik!$C$2:$Y$959,11,0) -> 5.6 | L11: =VLOOKUP(A11,Metrik!$C$2:$Y$959,12,0) -> 0.14 | M11: =VLOOKUP(A11,Metrik!$C$2:$Y$959,19,0) -> 20.9 | U11: =IFERROR(__xludf.DUMMYFUNCTION("IFERROR(GOOGLEFINANCE(A11,""closeyest""),"""")"),6050.0) -> 6050 | V11: =IFERROR(__xludf.DUMMYFUNCTION("IFERROR(GOOGLEFINANCE(A11,""changepct""),"""")"),2.07) -> 2.07 | W11: =IFERROR(__xludf.DUMMYFUNCTION("IFERROR(GOOGLEFINANCE(A11,""priceopen""),"""")"),6075.0) -> 6075 | X11: =IFERROR(__xludf.DUMMYFUNCTION("IFERROR(GOOGLEFINANCE(A11,""high""),"""")"),6325.0) -> 6325 | Y11: =IFERROR(__xludf.DUMMYFUNCTION("IFERROR(GOOGLEFINANCE(A11,""low""),"""")"),6025.0) -> 6025 | Z11: =IFERROR(__xludf.DUMMYFUNCTION("IFERROR(GOOGLEFINANCE(A11,""volume""),"""")"),3068700.0) -> 3068700 | AA11: =VLOOKUP(A11,Metrik!$C$2:$Y$959,5,0) -> Agricultural Products | AB11: =VLOOKUP(A11,Metrik!$C$2:$Y$959,3,0) -> Consumer Non-Cyclicals
A12: AALI | B12: {=VLOOKUP(A12,{Metrik!$C$2:$C$998,Metrik!$B$2:$B$998},2,0)} -> Astra Agro Lestari Tbk | C12: =IFERROR(__xludf.DUMMYFUNCTION("GOOGLEFINANCE(""IDX:""&A12,""price"")"),6175.0) -> 6175 | D12: =IFERROR(__xludf.DUMMYFUNCTION("IF(A12="""","""", SPARKLINE( INDEX( GOOGLEFINANCE(""IDX:""&A12,""close"",TODAY()-365,TODAY()), ,2 ), {""linewidth"",1} )) "),"#N/A") -> #N/A | E12: Investor33 | F12: 46356 | G12: =COUNTIFS($B$2:$B$1937,B12,$E$2:$E$1937,"<>") -> 2 | H12: =VLOOKUP(A12,Metrik!$C$2:$Y$959,8,0) -> 8 | I12: =VLOOKUP(A12,Metrik!$C$2:$Y$959,9,0) -> 0.51 | J12: =VLOOKUP(A12,Metrik!$C$2:$Y$959,10,0) -> 6.4 | K12: =VLOOKUP(A12,Metrik!$C$2:$Y$959,11,0) -> 5.6 | L12: =VLOOKUP(A12,Metrik!$C$2:$Y$959,12,0) -> 0.14 | M12: =VLOOKUP(A12,Metrik!$C$2:$Y$959,19,0) -> 20.9 | U12: =IFERROR(__xludf.DUMMYFUNCTION("IFERROR(GOOGLEFINANCE(A12,""closeyest""),"""")"),6050.0) -> 6050 | V12: =IFERROR(__xludf.DUMMYFUNCTION("IFERROR(GOOGLEFINANCE(A12,""changepct""),"""")"),2.07) -> 2.07 | W12: =IFERROR(__xludf.DUMMYFUNCTION("IFERROR(GOOGLEFINANCE(A12,""priceopen""),"""")"),6075.0) -> 6075 | X12: =IFERROR(__xludf.DUMMYFUNCTION("IFERROR(GOOGLEFINANCE(A12,""high""),"""")"),6325.0) -> 6325 | Y12: =IFERROR(__xludf.DUMMYFUNCTION("IFERROR(GOOGLEFINANCE(A12,""low""),"""")"),6025.0) -> 6025 | Z12: =IFERROR(__xludf.DUMMYFUNCTION("IFERROR(GOOGLEFINANCE(A12,""volume""),"""")"),3068700.0) -> 3068700 | AA12: =VLOOKUP(A12,Metrik!$C$2:$Y$959,5,0) -> Agricultural Products | AB12: =VLOOKUP(A12,Metrik!$C$2:$Y$959,3,0) -> Consumer Non-Cyclicals
A13: ABBA | B13: {=VLOOKUP(A13,{Metrik!$C$2:$C$998,Metrik!$B$2:$B$998},2,0)} -> Mahaka Media Tbk. | C13: =IFERROR(__xludf.DUMMYFUNCTION("GOOGLEFINANCE(""IDX:""&A13,""price"")"),35.0) -> 35 | D13: =IFERROR(__xludf.DUMMYFUNCTION("IF(A13="""","""", SPARKLINE( INDEX( GOOGLEFINANCE(""IDX:""&A13,""close"",TODAY()-365,TODAY()), ,2 ), {""linewidth"",1} )) "),"#N/A") -> #N/A | G13: =COUNTIFS($B$2:$B$1937,B13,$E$2:$E$1937,"<>") -> 0 | H13: =VLOOKUP(A13,Metrik!$C$2:$Y$959,8,0) -> -5.5 | I13: =VLOOKUP(A13,Metrik!$C$2:$Y$959,9,0) -> -1.3 | J13: =VLOOKUP(A13,Metrik!$C$2:$Y$959,10,0) -> 0 | K13: =VLOOKUP(A13,Metrik!$C$2:$Y$959,11,0) -> -11.1 | L13: =VLOOKUP(A13,Metrik!$C$2:$Y$959,12,0) -> -3.1 | M13: =VLOOKUP(A13,Metrik!$C$2:$Y$959,19,0) -> -91.1 | U13: =IFERROR(__xludf.DUMMYFUNCTION("IFERROR(GOOGLEFINANCE(A13,""closeyest""),"""")"),35.0) -> 35 | V13: =IFERROR(__xludf.DUMMYFUNCTION("IFERROR(GOOGLEFINANCE(A13,""changepct""),"""")"),0.0) -> 0 | W13: =IFERROR(__xludf.DUMMYFUNCTION("IFERROR(GOOGLEFINANCE(A13,""priceopen""),"""")"),35.0) -> 35 | X13: =IFERROR(__xludf.DUMMYFUNCTION("IFERROR(GOOGLEFINANCE(A13,""high""),"""")"),35.0) -> 35 | Y13: =IFERROR(__xludf.DUMMYFUNCTION("IFERROR(GOOGLEFINANCE(A13,""low""),"""")"),35.0) -> 35 | Z13: =IFERROR(__xludf.DUMMYFUNCTION("IFERROR(GOOGLEFINANCE(A13,""volume""),"""")"),292000.0) -> 292000 | AA13: =VLOOKUP(A13,Metrik!$C$2:$Y$959,5,0) -> Media | AB13: =VLOOKUP(A13,Metrik!$C$2:$Y$959,3,0) -> Consumer Cyclicals
A14: ABDA | B14: {=VLOOKUP(A14,{Metrik!$C$2:$C$998,Metrik!$B$2:$B$998},2,0)} -> Asuransi Bina Dana Arta Tbk. | C14: =IFERROR(__xludf.DUMMYFUNCTION("GOOGLEFINANCE(""IDX:""&A14,""price"")"),3390.0) -> 3390 | D14: =IFERROR(__xludf.DUMMYFUNCTION("IF(A14="""","""", SPARKLINE( INDEX( GOOGLEFINANCE(""IDX:""&A14,""close"",TODAY()-365,TODAY()), ,2 ), {""linewidth"",1} )) "),"#N/A") -> #N/A | G14: =COUNTIFS($B$2:$B$1937,B14,$E$2:$E$1937,"<>") -> 0 | H14: =VLOOKUP(A14,Metrik!$C$2:$Y$959,8,0) -> 19.6 | I14: =VLOOKUP(A14,Metrik!$C$2:$Y$959,9,0) -> 1.2 | J14: =VLOOKUP(A14,Metrik!$C$2:$Y$959,10,0) -> 6.3 | K14: =VLOOKUP(A14,Metrik!$C$2:$Y$959,11,0) -> 3.9 | L14: =VLOOKUP(A14,Metrik!$C$2:$Y$959,12,0) -> 0.59 | M14: =VLOOKUP(A14,Metrik!$C$2:$Y$959,19,0) -> 31.1 | U14: =IFERROR(__xludf.DUMMYFUNCTION("IFERROR(GOOGLEFINANCE(A14,""closeyest""),"""")"),3330.0) -> 3330 | V14: =IFERROR(__xludf.DUMMYFUNCTION("IFERROR(GOOGLEFINANCE(A14,""changepct""),"""")"),1.8) -> 1.8 | W14: =IFERROR(__xludf.DUMMYFUNCTION("IFERROR(GOOGLEFINANCE(A14,""priceopen""),"""")"),3430.0) -> 3430 | X14: =IFERROR(__xludf.DUMMYFUNCTION("IFERROR(GOOGLEFINANCE(A14,""high""),"""")"),3430.0) -> 3430 | Y14: =IFERROR(__xludf.DUMMYFUNCTION("IFERROR(GOOGLEFINANCE(A14,""low""),"""")"),3100.0) -> 3100 | Z14: =IFERROR(__xludf.DUMMYFUNCTION("IFERROR(GOOGLEFINANCE(A14,""volume""),"""")"),10200.0) -> 10200 | AA14: =VLOOKUP(A14,Metrik!$C$2:$Y$959,5,0) -> Insurance | AB14: =VLOOKUP(A14,Metrik!$C$2:$Y$959,3,0) -> Financials
A15: ABMM | B15: {=VLOOKUP(A15,{Metrik!$C$2:$C$998,Metrik!$B$2:$B$998},2,0)} -> ABM Investama Tbk | C15: =IFERROR(__xludf.DUMMYFUNCTION("GOOGLEFINANCE(""IDX:""&A15,""price"")"),2420.0) -> 2420 | D15: =IFERROR(__xludf.DUMMYFUNCTION("IF(A15="""","""", SPARKLINE( INDEX( GOOGLEFINANCE(""IDX:""&A15,""close"",TODAY()-365,TODAY()), ,2 ), {""linewidth"",1} )) "),"#N/A") -> #N/A | G15: =COUNTIFS($B$2:$B$1937,B15,$E$2:$E$1937,"<>") -> 0 | H15: =VLOOKUP(A15,Metrik!$C$2:$Y$959,8,0) -> 6.2 | I15: =VLOOKUP(A15,Metrik!$C$2:$Y$959,9,0) -> 0.43 | J15: =VLOOKUP(A15,Metrik!$C$2:$Y$959,10,0) -> 7.1 | K15: =VLOOKUP(A15,Metrik!$C$2:$Y$959,11,0) -> 3.1 | L15: =VLOOKUP(A15,Metrik!$C$2:$Y$959,12,0) -> 1.3 | M15: =VLOOKUP(A15,Metrik!$C$2:$Y$959,19,0) -> 28.4 | U15: =IFERROR(__xludf.DUMMYFUNCTION("IFERROR(GOOGLEFINANCE(A15,""closeyest""),"""")"),2300.0) -> 2300 | V15: =IFERROR(__xludf.DUMMYFUNCTION("IFERROR(GOOGLEFINANCE(A15,""changepct""),"""")"),5.22) -> 5.22 | W15: =IFERROR(__xludf.DUMMYFUNCTION("IFERROR(GOOGLEFINANCE(A15,""priceopen""),"""")"),2300.0) -> 2300 | X15: =IFERROR(__xludf.DUMMYFUNCTION("IFERROR(GOOGLEFINANCE(A15,""high""),"""")"),"") | Y15: =IFERROR(__xludf.DUMMYFUNCTION("IFERROR(GOOGLEFINANCE(A15,""low""),"""")"),2300.0) -> 2300 | Z15: =IFERROR(__xludf.DUMMYFUNCTION("IFERROR(GOOGLEFINANCE(A15,""volume""),"""")"),739300.0) -> 739300 | AA15: =VLOOKUP(A15,Metrik!$C$2:$Y$959,5,0) -> Multi-sector Holdings | AB15: =VLOOKUP(A15,Metrik!$C$2:$Y$959,3,0) -> Industrials
A16: ACES | B16: {=VLOOKUP(A16,{Metrik!$C$2:$C$998,Metrik!$B$2:$B$998},2,0)} -> Aspirasi Hidup Indonesia Tbk. | C16: =IFERROR(__xludf.DUMMYFUNCTION("GOOGLEFINANCE(""IDX:""&A16,""price"")"),356.0) -> 356 | D16: =IFERROR(__xludf.DUMMYFUNCTION("IF(A16="""","""", SPARKLINE( INDEX( GOOGLEFINANCE(""IDX:""&A16,""close"",TODAY()-365,TODAY()), ,2 ), {""linewidth"",1} )) "),"#N/A") -> #N/A | E16: ESGQKEHATI | F16: 46356 | G16: =COUNTIFS($B$2:$B$1937,B16,$E$2:$E$1937,"<>") -> 11 | H16: =VLOOKUP(A16,Metrik!$C$2:$Y$959,8,0) -> 8.6 | I16: =VLOOKUP(A16,Metrik!$C$2:$Y$959,9,0) -> 0.88 | J16: =VLOOKUP(A16,Metrik!$C$2:$Y$959,10,0) -> 10.2 | K16: =VLOOKUP(A16,Metrik!$C$2:$Y$959,11,0) -> 8 | L16: =VLOOKUP(A16,Metrik!$C$2:$Y$959,12,0) -> 0.28 | M16: =VLOOKUP(A16,Metrik!$C$2:$Y$959,19,0) -> 29.4 | U16: =IFERROR(__xludf.DUMMYFUNCTION("IFERROR(GOOGLEFINANCE(A16,""closeyest""),"""")"),36.5) -> 36.5 | V16: =IFERROR(__xludf.DUMMYFUNCTION("IFERROR(GOOGLEFINANCE(A16,""changepct""),"""")"),1.12) -> 1.12 | W16: =IFERROR(__xludf.DUMMYFUNCTION("IFERROR(GOOGLEFINANCE(A16,""priceopen""),"""")"),36.6) -> 36.6 | X16: =IFERROR(__xludf.DUMMYFUNCTION("IFERROR(GOOGLEFINANCE(A16,""high""),"""")"),36.98) -> 36.98 | Y16: =IFERROR(__xludf.DUMMYFUNCTION("IFERROR(GOOGLEFINANCE(A16,""low""),"""")"),36.6) -> 36.6 | Z16: =IFERROR(__xludf.DUMMYFUNCTION("IFERROR(GOOGLEFINANCE(A16,""volume""),"""")"),846.0) -> 846 | AA16: =VLOOKUP(A16,Metrik!$C$2:$Y$959,5,0) -> Specialty Retail | AB16: =VLOOKUP(A16,Metrik!$C$2:$Y$959,3,0) -> Consumer Cyclicals
A17: ACES | B17: {=VLOOKUP(A17,{Metrik!$C$2:$C$998,Metrik!$B$2:$B$998},2,0)} -> Aspirasi Hidup Indonesia Tbk. | C17: =IFERROR(__xludf.DUMMYFUNCTION("GOOGLEFINANCE(""IDX:""&A17,""price"")"),356.0) -> 356 | D17: =IFERROR(__xludf.DUMMYFUNCTION("IF(A17="""","""", SPARKLINE( INDEX( GOOGLEFINANCE(""IDX:""&A17,""close"",TODAY()-365,TODAY()), ,2 ), {""linewidth"",1} )) "),"#N/A") -> #N/A | E17: IDXHIDIV20 | F17: 2 Februari 2027 | G17: =COUNTIFS($B$2:$B$1937,B17,$E$2:$E$1937,"<>") -> 11 | H17: =VLOOKUP(A17,Metrik!$C$2:$Y$959,8,0) -> 8.6 | I17: =VLOOKUP(A17,Metrik!$C$2:$Y$959,9,0) -> 0.88 | J17: =VLOOKUP(A17,Metrik!$C$2:$Y$959,10,0) -> 10.2 | K17: =VLOOKUP(A17,Metrik!$C$2:$Y$959,11,0) -> 8 | L17: =VLOOKUP(A17,Metrik!$C$2:$Y$959,12,0) -> 0.28 | M17: =VLOOKUP(A17,Metrik!$C$2:$Y$959,19,0) -> 29.4 | U17: =IFERROR(__xludf.DUMMYFUNCTION("IFERROR(GOOGLEFINANCE(A17,""closeyest""),"""")"),36.5) -> 36.5 | V17: =IFERROR(__xludf.DUMMYFUNCTION("IFERROR(GOOGLEFINANCE(A17,""changepct""),"""")"),1.12) -> 1.12 | W17: =IFERROR(__xludf.DUMMYFUNCTION("IFERROR(GOOGLEFINANCE(A17,""priceopen""),"""")"),36.6) -> 36.6 | X17: =IFERROR(__xludf.DUMMYFUNCTION("IFERROR(GOOGLEFINANCE(A17,""high""),"""")"),36.98) -> 36.98 | Y17: =IFERROR(__xludf.DUMMYFUNCTION("IFERROR(GOOGLEFINANCE(A17,""low""),"""")"),36.6) -> 36.6 | Z17: =IFERROR(__xludf.DUMMYFUNCTION("IFERROR(GOOGLEFINANCE(A17,""volume""),"""")"),846.0) -> 846 | AA17: =VLOOKUP(A17,Metrik!$C$2:$Y$959,5,0) -> Specialty Retail | AB17: =VLOOKUP(A17,Metrik!$C$2:$Y$959,3,0) -> Consumer Cyclicals
A18: ACES | B18: {=VLOOKUP(A18,{Metrik!$C$2:$C$998,Metrik!$B$2:$B$998},2,0)} -> Aspirasi Hidup Indonesia Tbk. | C18: =IFERROR(__xludf.DUMMYFUNCTION("GOOGLEFINANCE(""IDX:""&A18,""price"")"),356.0) -> 356 | D18: =IFERROR(__xludf.DUMMYFUNCTION("IF(A18="""","""", SPARKLINE( INDEX( GOOGLEFINANCE(""IDX:""&A18,""close"",TODAY()-365,TODAY()), ,2 ), {""linewidth"",1} )) "),"#N/A") -> #N/A | E18: IDX80 | F18: 31 Juli 2026 | G18: =COUNTIFS($B$2:$B$1937,B18,$E$2:$E$1937,"<>") -> 11 | H18: =VLOOKUP(A18,Metrik!$C$2:$Y$959,8,0) -> 8.6 | I18: =VLOOKUP(A18,Metrik!$C$2:$Y$959,9,0) -> 0.88 | J18: =VLOOKUP(A18,Metrik!$C$2:$Y$959,10,0) -> 10.2 | K18: =VLOOKUP(A18,Metrik!$C$2:$Y$959,11,0) -> 8 | L18: =VLOOKUP(A18,Metrik!$C$2:$Y$959,12,0) -> 0.28 | M18: =VLOOKUP(A18,Metrik!$C$2:$Y$959,19,0) -> 29.4 | U18: =IFERROR(__xludf.DUMMYFUNCTION("IFERROR(GOOGLEFINANCE(A18,""closeyest""),"""")"),36.5) -> 36.5 | V18: =IFERROR(__xludf.DUMMYFUNCTION("IFERROR(GOOGLEFINANCE(A18,""changepct""),"""")"),1.12) -> 1.12 | W18: =IFERROR(__xludf.DUMMYFUNCTION("IFERROR(GOOGLEFINANCE(A18,""priceopen""),"""")"),36.6) -> 36.6 | X18: =IFERROR(__xludf.DUMMYFUNCTION("IFERROR(GOOGLEFINANCE(A18,""high""),"""")"),36.98) -> 36.98 | Y18: =IFERROR(__xludf.DUMMYFUNCTION("IFERROR(GOOGLEFINANCE(A18,""low""),"""")"),36.6) -> 36.6 | Z18: =IFERROR(__xludf.DUMMYFUNCTION("IFERROR(GOOGLEFINANCE(A18,""volume""),"""")"),846.0) -> 846 | AA18: =VLOOKUP(A18,Metrik!$C$2:$Y$959,5,0) -> Specialty Retail | AB18: =VLOOKUP(A18,Metrik!$C$2:$Y$959,3,0) -> Consumer Cyclicals
A19: ACES | B19: {=VLOOKUP(A19,{Metrik!$C$2:$C$998,Metrik!$B$2:$B$998},2,0)} -> Aspirasi Hidup Indonesia Tbk. | C19: =IFERROR(__xludf.DUMMYFUNCTION("GOOGLEFINANCE(""IDX:""&A19,""price"")"),356.0) -> 356 | D19: =IFERROR(__xludf.DUMMYFUNCTION("IF(A19="""","""", SPARKLINE( INDEX( GOOGLEFINANCE(""IDX:""&A19,""close"",TODAY()-365,TODAY()), ,2 ), {""linewidth"",1} )) "),"#N/A") -> #N/A | E19: IDXESGL | F19: 30 Oktober 2026 | G19: =COUNTIFS($B$2:$B$1937,B19,$E$2:$E$1937,"<>") -> 11 | H19: =VLOOKUP(A19,Metrik!$C$2:$Y$959,8,0) -> 8.6 | I19: =VLOOKUP(A19,Metrik!$C$2:$Y$959,9,0) -> 0.88 | J19: =VLOOKUP(A19,Metrik!$C$2:$Y$959,10,0) -> 10.2 | K19: =VLOOKUP(A19,Metrik!$C$2:$Y$959,11,0) -> 8 | L19: =VLOOKUP(A19,Metrik!$C$2:$Y$959,12,0) -> 0.28 | M19: =VLOOKUP(A19,Metrik!$C$2:$Y$959,19,0) -> 29.4 | U19: =IFERROR(__xludf.DUMMYFUNCTION("IFERROR(GOOGLEFINANCE(A19,""closeyest""),"""")"),36.5) -> 36.5 | V19: =IFERROR(__xludf.DUMMYFUNCTION("IFERROR(GOOGLEFINANCE(A19,""changepct""),"""")"),1.12) -> 1.12 | W19: =IFERROR(__xludf.DUMMYFUNCTION("IFERROR(GOOGLEFINANCE(A19,""priceopen""),"""")"),36.6) -> 36.6 | X19: =IFERROR(__xludf.DUMMYFUNCTION("IFERROR(GOOGLEFINANCE(A19,""high""),"""")"),36.98) -> 36.98 | Y19: =IFERROR(__xludf.DUMMYFUNCTION("IFERROR(GOOGLEFINANCE(A19,""low""),"""")"),36.6) -> 36.6 | Z19: =IFERROR(__xludf.DUMMYFUNCTION("IFERROR(GOOGLEFINANCE(A19,""volume""),"""")"),846.0) -> 846 | AA19: =VLOOKUP(A19,Metrik!$C$2:$Y$959,5,0) -> Specialty Retail | AB19: =VLOOKUP(A19,Metrik!$C$2:$Y$959,3,0) -> Consumer Cyclicals
A20: ACES | B20: {=VLOOKUP(A20,{Metrik!$C$2:$C$998,Metrik!$B$2:$B$998},2,0)} -> Aspirasi Hidup Indonesia Tbk. | C20: =IFERROR(__xludf.DUMMYFUNCTION("GOOGLEFINANCE(""IDX:""&A20,""price"")"),356.0) -> 356 | D20: =IFERROR(__xludf.DUMMYFUNCTION("IF(A20="""","""", SPARKLINE( INDEX( GOOGLEFINANCE(""IDX:""&A20,""close"",TODAY()-365,TODAY()), ,2 ), {""linewidth"",1} )) "),"#N/A") -> #N/A | E20: ECONOMIC30 | F20: 31 Agustus 2026 | G20: =COUNTIFS($B$2:$B$1937,B20,$E$2:$E$1937,"<>") -> 11 | H20: =VLOOKUP(A20,Metrik!$C$2:$Y$959,8,0) -> 8.6 | I20: =VLOOKUP(A20,Metrik!$C$2:$Y$959,9,0) -> 0.88 | J20: =VLOOKUP(A20,Metrik!$C$2:$Y$959,10,0) -> 10.2 | K20: =VLOOKUP(A20,Metrik!$C$2:$Y$959,11,0) -> 8 | L20: =VLOOKUP(A20,Metrik!$C$2:$Y$959,12,0) -> 0.28 | M20: =VLOOKUP(A20,Metrik!$C$2:$Y$959,19,0) -> 29.4 | U20: =IFERROR(__xludf.DUMMYFUNCTION("IFERROR(GOOGLEFINANCE(A20,""closeyest""),"""")"),36.5) -> 36.5 | V20: =IFERROR(__xludf.DUMMYFUNCTION("IFERROR(GOOGLEFINANCE(A20,""changepct""),"""")"),1.12) -> 1.12 | W20: =IFERROR(__xludf.DUMMYFUNCTION("IFERROR(GOOGLEFINANCE(A20,""priceopen""),"""")"),36.6) -> 36.6 | X20: =IFERROR(__xludf.DUMMYFUNCTION("IFERROR(GOOGLEFINANCE(A20,""high""),"""")"),36.98) -> 36.98 | Y20: =IFERROR(__xludf.DUMMYFUNCTION("IFERROR(GOOGLEFINANCE(A20,""low""),"""")"),36.6) -> 36.6 | Z20: =IFERROR(__xludf.DUMMYFUNCTION("IFERROR(GOOGLEFINANCE(A20,""volume""),"""")"),846.0) -> 846 | AA20: =VLOOKUP(A20,Metrik!$C$2:$Y$959,5,0) -> Specialty Retail | AB20: =VLOOKUP(A20,Metrik!$C$2:$Y$959,3,0) -> Consumer Cyclicals
A21: ACES | B21: {=VLOOKUP(A21,{Metrik!$C$2:$C$998,Metrik!$B$2:$B$998},2,0)} -> Aspirasi Hidup Indonesia Tbk. | C21: =IFERROR(__xludf.DUMMYFUNCTION("GOOGLEFINANCE(""IDX:""&A21,""price"")"),356.0) -> 356 | D21: =IFERROR(__xludf.DUMMYFUNCTION("IF(A21="""","""", SPARKLINE( INDEX( GOOGLEFINANCE(""IDX:""&A21,""close"",TODAY()-365,TODAY()), ,2 ), {""linewidth"",1} )) "),"#N/A") -> #N/A | E21: Kompas100 | F21: 31 Juli 2026 | G21: =COUNTIFS($B$2:$B$1937,B21,$E$2:$E$1937,"<>") -> 11 | H21: =VLOOKUP(A21,Metrik!$C$2:$Y$959,8,0) -> 8.6 | I21: =VLOOKUP(A21,Metrik!$C$2:$Y$959,9,0) -> 0.88 | J21: =VLOOKUP(A21,Metrik!$C$2:$Y$959,10,0) -> 10.2 | K21: =VLOOKUP(A21,Metrik!$C$2:$Y$959,11,0) -> 8 | L21: =VLOOKUP(A21,Metrik!$C$2:$Y$959,12,0) -> 0.28 | M21: =VLOOKUP(A21,Metrik!$C$2:$Y$959,19,0) -> 29.4 | U21: =IFERROR(__xludf.DUMMYFUNCTION("IFERROR(GOOGLEFINANCE(A21,""closeyest""),"""")"),36.5) -> 36.5 | V21: =IFERROR(__xludf.DUMMYFUNCTION("IFERROR(GOOGLEFINANCE(A21,""changepct""),"""")"),1.12) -> 1.12 | W21: =IFERROR(__xludf.DUMMYFUNCTION("IFERROR(GOOGLEFINANCE(A21,""priceopen""),"""")"),36.6) -> 36.6 | X21: =IFERROR(__xludf.DUMMYFUNCTION("IFERROR(GOOGLEFINANCE(A21,""high""),"""")"),36.98) -> 36.98 | Y21: =IFERROR(__xludf.DUMMYFUNCTION("IFERROR(GOOGLEFINANCE(A21,""low""),"""")"),36.6) -> 36.6 | Z21: =IFERROR(__xludf.DUMMYFUNCTION("IFERROR(GOOGLEFINANCE(A21,""volume""),"""")"),846.0) -> 846 | AA21: =VLOOKUP(A21,Metrik!$C$2:$Y$959,5,0) -> Specialty Retail | AB21: =VLOOKUP(A21,Metrik!$C$2:$Y$959,3,0) -> Consumer Cyclicals
A22: ACES | B22: {=VLOOKUP(A22,{Metrik!$C$2:$C$998,Metrik!$B$2:$B$998},2,0)} -> Aspirasi Hidup Indonesia Tbk. | C22: =IFERROR(__xludf.DUMMYFUNCTION("GOOGLEFINANCE(""IDX:""&A22,""price"")"),356.0) -> 356 | D22: =IFERROR(__xludf.DUMMYFUNCTION("IF(A22="""","""", SPARKLINE( INDEX( GOOGLEFINANCE(""IDX:""&A22,""close"",TODAY()-365,TODAY()), ,2 ), {""linewidth"",1} )) "),"#N/A") -> #N/A | E22: IDXQ30 | F22: 4 Agustus 2026 | G22: =COUNTIFS($B$2:$B$1937,B22,$E$2:$E$1937,"<>") -> 11 | H22: =VLOOKUP(A22,Metrik!$C$2:$Y$959,8,0) -> 8.6 | I22: =VLOOKUP(A22,Metrik!$C$2:$Y$959,9,0) -> 0.88 | J22: =VLOOKUP(A22,Metrik!$C$2:$Y$959,10,0) -> 10.2 | K22: =VLOOKUP(A22,Metrik!$C$2:$Y$959,11,0) -> 8 | L22: =VLOOKUP(A22,Metrik!$C$2:$Y$959,12,0) -> 0.28 | M22: =VLOOKUP(A22,Metrik!$C$2:$Y$959,19,0) -> 29.4 | U22: =IFERROR(__xludf.DUMMYFUNCTION("IFERROR(GOOGLEFINANCE(A22,""closeyest""),"""")"),36.5) -> 36.5 | V22: =IFERROR(__xludf.DUMMYFUNCTION("IFERROR(GOOGLEFINANCE(A22,""changepct""),"""")"),1.12) -> 1.12 | W22: =IFERROR(__xludf.DUMMYFUNCTION("IFERROR(GOOGLEFINANCE(A22,""priceopen""),"""")"),36.6) -> 36.6 | X22: =IFERROR(__xludf.DUMMYFUNCTION("IFERROR(GOOGLEFINANCE(A22,""high""),"""")"),36.98) -> 36.98 | Y22: =IFERROR(__xludf.DUMMYFUNCTION("IFERROR(GOOGLEFINANCE(A22,""low""),"""")"),36.6) -> 36.6 | Z22: =IFERROR(__xludf.DUMMYFUNCTION("IFERROR(GOOGLEFINANCE(A22,""volume""),"""")"),846.0) -> 846 | AA22: =VLOOKUP(A22,Metrik!$C$2:$Y$959,5,0) -> Specialty Retail | AB22: =VLOOKUP(A22,Metrik!$C$2:$Y$959,3,0) -> Consumer Cyclicals
A23: ACES | B23: {=VLOOKUP(A23,{Metrik!$C$2:$C$998,Metrik!$B$2:$B$998},2,0)} -> Aspirasi Hidup Indonesia Tbk. | C23: =IFERROR(__xludf.DUMMYFUNCTION("GOOGLEFINANCE(""IDX:""&A23,""price"")"),356.0) -> 356 | D23: =IFERROR(__xludf.DUMMYFUNCTION("IF(A23="""","""", SPARKLINE( INDEX( GOOGLEFINANCE(""IDX:""&A23,""close"",TODAY()-365,TODAY()), ,2 ), {""linewidth"",1} )) "),"#N/A") -> #N/A | E23: IDXSMC-LIQ | F23: 4 Agustus 2026 | G23: =COUNTIFS($B$2:$B$1937,B23,$E$2:$E$1937,"<>") -> 11 | H23: =VLOOKUP(A23,Metrik!$C$2:$Y$959,8,0) -> 8.6 | I23: =VLOOKUP(A23,Metrik!$C$2:$Y$959,9,0) -> 0.88 | J23: =VLOOKUP(A23,Metrik!$C$2:$Y$959,10,0) -> 10.2 | K23: =VLOOKUP(A23,Metrik!$C$2:$Y$959,11,0) -> 8 | L23: =VLOOKUP(A23,Metrik!$C$2:$Y$959,12,0) -> 0.28 | M23: =VLOOKUP(A23,Metrik!$C$2:$Y$959,19,0) -> 29.4 | U23: =IFERROR(__xludf.DUMMYFUNCTION("IFERROR(GOOGLEFINANCE(A23,""closeyest""),"""")"),36.5) -> 36.5 | V23: =IFERROR(__xludf.DUMMYFUNCTION("IFERROR(GOOGLEFINANCE(A23,""changepct""),"""")"),1.12) -> 1.12 | W23: =IFERROR(__xludf.DUMMYFUNCTION("IFERROR(GOOGLEFINANCE(A23,""priceopen""),"""")"),36.6) -> 36.6 | X23: =IFERROR(__xludf.DUMMYFUNCTION("IFERROR(GOOGLEFINANCE(A23,""high""),"""")"),36.98) -> 36.98 | Y23: =IFERROR(__xludf.DUMMYFUNCTION("IFERROR(GOOGLEFINANCE(A23,""low""),"""")"),36.6) -> 36.6 | Z23: =IFERROR(__xludf.DUMMYFUNCTION("IFERROR(GOOGLEFINANCE(A23,""volume""),"""")"),846.0) -> 846 | AA23: =VLOOKUP(A23,Metrik!$C$2:$Y$959,5,0) -> Specialty Retail | AB23: =VLOOKUP(A23,Metrik!$C$2:$Y$959,3,0) -> Consumer Cyclicals
A24: ACES | B24: {=VLOOKUP(A24,{Metrik!$C$2:$C$998,Metrik!$B$2:$B$998},2,0)} -> Aspirasi Hidup Indonesia Tbk. | C24: =IFERROR(__xludf.DUMMYFUNCTION("GOOGLEFINANCE(""IDX:""&A24,""price"")"),356.0) -> 356 | D24: =IFERROR(__xludf.DUMMYFUNCTION("IF(A24="""","""", SPARKLINE( INDEX( GOOGLEFINANCE(""IDX:""&A24,""close"",TODAY()-365,TODAY()), ,2 ), {""linewidth"",1} )) "),"#N/A") -> #N/A | E24: IDXV30 | F24: 4 Agustus 2026 | G24: =COUNTIFS($B$2:$B$1937,B24,$E$2:$E$1937,"<>") -> 11 | H24: =VLOOKUP(A24,Metrik!$C$2:$Y$959,8,0) -> 8.6 | I24: =VLOOKUP(A24,Metrik!$C$2:$Y$959,9,0) -> 0.88 | J24: =VLOOKUP(A24,Metrik!$C$2:$Y$959,10,0) -> 10.2 | K24: =VLOOKUP(A24,Metrik!$C$2:$Y$959,11,0) -> 8 | L24: =VLOOKUP(A24,Metrik!$C$2:$Y$959,12,0) -> 0.28 | M24: =VLOOKUP(A24,Metrik!$C$2:$Y$959,19,0) -> 29.4 | U24: =IFERROR(__xludf.DUMMYFUNCTION("IFERROR(GOOGLEFINANCE(A24,""closeyest""),"""")"),36.5) -> 36.5 | V24: =IFERROR(__xludf.DUMMYFUNCTION("IFERROR(GOOGLEFINANCE(A24,""changepct""),"""")"),1.12) -> 1.12 | W24: =IFERROR(__xludf.DUMMYFUNCTION("IFERROR(GOOGLEFINANCE(A24,""priceopen""),"""")"),36.6) -> 36.6 | X24: =IFERROR(__xludf.DUMMYFUNCTION("IFERROR(GOOGLEFINANCE(A24,""high""),"""")"),36.98) -> 36.98 | Y24: =IFERROR(__xludf.DUMMYFUNCTION("IFERROR(GOOGLEFINANCE(A24,""low""),"""")"),36.6) -> 36.6 | Z24: =IFERROR(__xludf.DUMMYFUNCTION("IFERROR(GOOGLEFINANCE(A24,""volume""),"""")"),846.0) -> 846 | AA24: =VLOOKUP(A24,Metrik!$C$2:$Y$959,5,0) -> Specialty Retail | AB24: =VLOOKUP(A24,Metrik!$C$2:$Y$959,3,0) -> Consumer Cyclicals
A25: ACES | B25: {=VLOOKUP(A25,{Metrik!$C$2:$C$998,Metrik!$B$2:$B$998},2,0)} -> Aspirasi Hidup Indonesia Tbk. | C25: =IFERROR(__xludf.DUMMYFUNCTION("GOOGLEFINANCE(""IDX:""&A25,""price"")"),356.0) -> 356 | D25: =IFERROR(__xludf.DUMMYFUNCTION("IF(A25="""","""", SPARKLINE( INDEX( GOOGLEFINANCE(""IDX:""&A25,""close"",TODAY()-365,TODAY()), ,2 ), {""linewidth"",1} )) "),"#N/A") -> #N/A | E25: ESGSKEHATI | F25: 46356 | G25: =COUNTIFS($B$2:$B$1937,B25,$E$2:$E$1937,"<>") -> 11 | H25: =VLOOKUP(A25,Metrik!$C$2:$Y$959,8,0) -> 8.6 | I25: =VLOOKUP(A25,Metrik!$C$2:$Y$959,9,0) -> 0.88 | J25: =VLOOKUP(A25,Metrik!$C$2:$Y$959,10,0) -> 10.2 | K25: =VLOOKUP(A25,Metrik!$C$2:$Y$959,11,0) -> 8 | L25: =VLOOKUP(A25,Metrik!$C$2:$Y$959,12,0) -> 0.28 | M25: =VLOOKUP(A25,Metrik!$C$2:$Y$959,19,0) -> 29.4 | U25: =IFERROR(__xludf.DUMMYFUNCTION("IFERROR(GOOGLEFINANCE(A25,""closeyest""),"""")"),36.5) -> 36.5 | V25: =IFERROR(__xludf.DUMMYFUNCTION("IFERROR(GOOGLEFINANCE(A25,""changepct""),"""")"),1.12) -> 1.12 | W25: =IFERROR(__xludf.DUMMYFUNCTION("IFERROR(GOOGLEFINANCE(A25,""priceopen""),"""")"),36.6) -> 36.6 | X25: =IFERROR(__xludf.DUMMYFUNCTION("IFERROR(GOOGLEFINANCE(A25,""high""),"""")"),36.98) -> 36.98 | Y25: =IFERROR(__xludf.DUMMYFUNCTION("IFERROR(GOOGLEFINANCE(A25,""low""),"""")"),36.6) -> 36.6 | Z25: =IFERROR(__xludf.DUMMYFUNCTION("IFERROR(GOOGLEFINANCE(A25,""volume""),"""")"),846.0) -> 846 | AA25: =VLOOKUP(A25,Metrik!$C$2:$Y$959,5,0) -> Specialty Retail | AB25: =VLOOKUP(A25,Metrik!$C$2:$Y$959,3,0) -> Consumer Cyclicals
A26: ACES | B26: {=VLOOKUP(A26,{Metrik!$C$2:$C$998,Metrik!$B$2:$B$998},2,0)} -> Aspirasi Hidup Indonesia Tbk. | C26: =IFERROR(__xludf.DUMMYFUNCTION("GOOGLEFINANCE(""IDX:""&A26,""price"")"),356.0) -> 356 | D26: =IFERROR(__xludf.DUMMYFUNCTION("IF(A26="""","""", SPARKLINE( INDEX( GOOGLEFINANCE(""IDX:""&A26,""close"",TODAY()-365,TODAY()), ,2 ), {""linewidth"",1} )) "),"#N/A") -> #N/A | E26: JII70 | F26: 46356 | G26: =COUNTIFS($B$2:$B$1937,B26,$E$2:$E$1937,"<>") -> 11 | H26: =VLOOKUP(A26,Metrik!$C$2:$Y$959,8,0) -> 8.6 | I26: =VLOOKUP(A26,Metrik!$C$2:$Y$959,9,0) -> 0.88 | J26: =VLOOKUP(A26,Metrik!$C$2:$Y$959,10,0) -> 10.2 | K26: =VLOOKUP(A26,Metrik!$C$2:$Y$959,11,0) -> 8 | L26: =VLOOKUP(A26,Metrik!$C$2:$Y$959,12,0) -> 0.28 | M26: =VLOOKUP(A26,Metrik!$C$2:$Y$959,19,0) -> 29.4 | U26: =IFERROR(__xludf.DUMMYFUNCTION("IFERROR(GOOGLEFINANCE(A26,""closeyest""),"""")"),36.5) -> 36.5 | V26: =IFERROR(__xludf.DUMMYFUNCTION("IFERROR(GOOGLEFINANCE(A26,""changepct""),"""")"),1.12) -> 1.12 | W26: =IFERROR(__xludf.DUMMYFUNCTION("IFERROR(GOOGLEFINANCE(A26,""priceopen""),"""")"),36.6) -> 36.6 | X26: =IFERROR(__xludf.DUMMYFUNCTION("IFERROR(GOOGLEFINANCE(A26,""high""),"""")"),36.98) -> 36.98 | Y26: =IFERROR(__xludf.DUMMYFUNCTION("IFERROR(GOOGLEFINANCE(A26,""low""),"""")"),36.6) -> 36.6 | Z26: =IFERROR(__xludf.DUMMYFUNCTION("IFERROR(GOOGLEFINANCE(A26,""volume""),"""")"),846.0) -> 846 | AA26: =VLOOKUP(A26,Metrik!$C$2:$Y$959,5,0) -> Specialty Retail | AB26: =VLOOKUP(A26,Metrik!$C$2:$Y$959,3,0) -> Consumer Cyclicals
A27: ACRO | B27: {=VLOOKUP(A27,{Metrik!$C$2:$C$998,Metrik!$B$2:$B$998},2,0)} -> Samcro Hyosung Adilestari Tbk. | C27: =IFERROR(__xludf.DUMMYFUNCTION("GOOGLEFINANCE(""IDX:""&A27,""price"")"),61.0) -> 61 | D27: =IFERROR(__xludf.DUMMYFUNCTION("IF(A27="""","""", SPARKLINE( INDEX( GOOGLEFINANCE(""IDX:""&A27,""close"",TODAY()-365,TODAY()), ,2 ), {""linewidth"",1} )) "),"#N/A") -> #N/A | G27: =COUNTIFS($B$2:$B$1937,B27,$E$2:$E$1937,"<>") -> 0 | H27: =VLOOKUP(A27,Metrik!$C$2:$Y$959,8,0) -> 26.8 | I27: =VLOOKUP(A27,Metrik!$C$2:$Y$959,9,0) -> 1.2 | J27: =VLOOKUP(A27,Metrik!$C$2:$Y$959,10,0) -> 4.6 | K27: =VLOOKUP(A27,Metrik!$C$2:$Y$959,11,0) -> 3.5 | L27: =VLOOKUP(A27,Metrik!$C$2:$Y$959,12,0) -> 0.29 | M27: =VLOOKUP(A27,Metrik!$C$2:$Y$959,19,0) -> 70.6 | U27: =IFERROR(__xludf.DUMMYFUNCTION("IFERROR(GOOGLEFINANCE(A27,""closeyest""),"""")"),60.0) -> 60 | V27: =IFERROR(__xludf.DUMMYFUNCTION("IFERROR(GOOGLEFINANCE(A27,""changepct""),"""")"),1.67) -> 1.67 | W27: =IFERROR(__xludf.DUMMYFUNCTION("IFERROR(GOOGLEFINANCE(A27,""priceopen""),"""")"),60.0) -> 60 | X27: =IFERROR(__xludf.DUMMYFUNCTION("IFERROR(GOOGLEFINANCE(A27,""high""),"""")"),65.0) -> 65 | Y27: =IFERROR(__xludf.DUMMYFUNCTION("IFERROR(GOOGLEFINANCE(A27,""low""),"""")"),60.0) -> 60 | Z27: =IFERROR(__xludf.DUMMYFUNCTION("IFERROR(GOOGLEFINANCE(A27,""volume""),"""")"),3937300.0) -> 3937300 | AA27: =VLOOKUP(A27,Metrik!$C$2:$Y$959,5,0) -> Apparel & Luxury Goods | AB27: =VLOOKUP(A27,Metrik!$C$2:$Y$959,3,0) -> Consumer Cyclicals
A28: ACST | B28: {=VLOOKUP(A28,{Metrik!$C$2:$C$998,Metrik!$B$2:$B$998},2,0)} -> PT Acset Indonusa Tbk. | C28: =IFERROR(__xludf.DUMMYFUNCTION("GOOGLEFINANCE(""IDX:""&A28,""price"")"),71.0) -> 71 | D28: =IFERROR(__xludf.DUMMYFUNCTION("IF(A28="""","""", SPARKLINE( INDEX( GOOGLEFINANCE(""IDX:""&A28,""close"",TODAY()-365,TODAY()), ,2 ), {""linewidth"",1} )) "),"#N/A") -> #N/A | G28: =COUNTIFS($B$2:$B$1937,B28,$E$2:$E$1937,"<>") -> 0 | H28: =VLOOKUP(A28,Metrik!$C$2:$Y$959,8,0) -> -2.1 | I28: =VLOOKUP(A28,Metrik!$C$2:$Y$959,9,0) -> -4.4 | J28: =VLOOKUP(A28,Metrik!$C$2:$Y$959,10,0) -> 0 | K28: =VLOOKUP(A28,Metrik!$C$2:$Y$959,11,0) -> -23.3 | L28: =VLOOKUP(A28,Metrik!$C$2:$Y$959,12,0) -> -9.9 | M28: =VLOOKUP(A28,Metrik!$C$2:$Y$959,19,0) -> -150 | U28: =IFERROR(__xludf.DUMMYFUNCTION("IFERROR(GOOGLEFINANCE(A28,""closeyest""),"""")"),70.0) -> 70 | V28: =IFERROR(__xludf.DUMMYFUNCTION("IFERROR(GOOGLEFINANCE(A28,""changepct""),"""")"),1.43) -> 1.43 | W28: =IFERROR(__xludf.DUMMYFUNCTION("IFERROR(GOOGLEFINANCE(A28,""priceopen""),"""")"),70.0) -> 70 | X28: =IFERROR(__xludf.DUMMYFUNCTION("IFERROR(GOOGLEFINANCE(A28,""high""),"""")"),71.0) -> 71 | Y28: =IFERROR(__xludf.DUMMYFUNCTION("IFERROR(GOOGLEFINANCE(A28,""low""),"""")"),70.0) -> 70 | Z28: =IFERROR(__xludf.DUMMYFUNCTION("IFERROR(GOOGLEFINANCE(A28,""volume""),"""")"),173800.0) -> 173800 | AA28: =VLOOKUP(A28,Metrik!$C$2:$Y$959,5,0) -> Heavy Constructions & Civil Engineering | AB28: =VLOOKUP(A28,Metrik!$C$2:$Y$959,3,0) -> Infrastructures
A29: ADCP | B29: {=VLOOKUP(A29,{Metrik!$C$2:$C$998,Metrik!$B$2:$B$998},2,0)} -> Adhi Commuter Properti Tbk. | C29: =IFERROR(__xludf.DUMMYFUNCTION("GOOGLEFINANCE(""IDX:""&A29,""price"")"),50.0) -> 50 | D29: =IFERROR(__xludf.DUMMYFUNCTION("IF(A29="""","""", SPARKLINE( INDEX( GOOGLEFINANCE(""IDX:""&A29,""close"",TODAY()-365,TODAY()), ,2 ), {""linewidth"",1} )) "),"#N/A") -> #N/A | G29: =COUNTIFS($B$2:$B$1937,B29,$E$2:$E$1937,"<>") -> 0 | H29: =VLOOKUP(A29,Metrik!$C$2:$Y$959,8,0) -> -0.52 | I29: =VLOOKUP(A29,Metrik!$C$2:$Y$959,9,0) -> 2.8 | J29: =VLOOKUP(A29,Metrik!$C$2:$Y$959,10,0) -> -540 | K29: =VLOOKUP(A29,Metrik!$C$2:$Y$959,11,0) -> -42.2 | L29: =VLOOKUP(A29,Metrik!$C$2:$Y$959,12,0) -> 11.9 | M29: =VLOOKUP(A29,Metrik!$C$2:$Y$959,19,0) -> -5640 | U29: =IFERROR(__xludf.DUMMYFUNCTION("IFERROR(GOOGLEFINANCE(A29,""closeyest""),"""")"),50.0) -> 50 | V29: =IFERROR(__xludf.DUMMYFUNCTION("IFERROR(GOOGLEFINANCE(A29,""changepct""),"""")"),0.0) -> 0 | W29: =IFERROR(__xludf.DUMMYFUNCTION("IFERROR(GOOGLEFINANCE(A29,""priceopen""),"""")"),"") | X29: =IFERROR(__xludf.DUMMYFUNCTION("IFERROR(GOOGLEFINANCE(A29,""high""),"""")"),"") | Y29: =IFERROR(__xludf.DUMMYFUNCTION("IFERROR(GOOGLEFINANCE(A29,""low""),"""")"),"") | Z29: =IFERROR(__xludf.DUMMYFUNCTION("IFERROR(GOOGLEFINANCE(A29,""volume""),"""")"),0.0) -> 0 | AA29: =VLOOKUP(A29,Metrik!$C$2:$Y$959,5,0) -> Real Estate Management & Development | AB29: =VLOOKUP(A29,Metrik!$C$2:$Y$959,3,0) -> Properties & Real Estate
A30: ADES | B30: {=VLOOKUP(A30,{Metrik!$C$2:$C$998,Metrik!$B$2:$B$998},2,0)} -> Akasha Wira International Tbk. | C30: =IFERROR(__xludf.DUMMYFUNCTION("GOOGLEFINANCE(""IDX:""&A30,""price"")"),22000.0) -> 22000 | D30: =IFERROR(__xludf.DUMMYFUNCTION("IF(A30="""","""", SPARKLINE( INDEX( GOOGLEFINANCE(""IDX:""&A30,""close"",TODAY()-365,TODAY()), ,2 ), {""linewidth"",1} )) "),"#N/A") -> #N/A | G30: =COUNTIFS($B$2:$B$1937,B30,$E$2:$E$1937,"<>") -> 0 | H30: =VLOOKUP(A30,Metrik!$C$2:$Y$959,8,0) -> 14.6 | I30: =VLOOKUP(A30,Metrik!$C$2:$Y$959,9,0) -> 3.8 | J30: =VLOOKUP(A30,Metrik!$C$2:$Y$959,10,0) -> 26.1 | K30: =VLOOKUP(A30,Metrik!$C$2:$Y$959,11,0) -> 21.6 | L30: =VLOOKUP(A30,Metrik!$C$2:$Y$959,12,0) -> 0.21 | M30: =VLOOKUP(A30,Metrik!$C$2:$Y$959,19,0) -> 90.3 | U30: =IFERROR(__xludf.DUMMYFUNCTION("IFERROR(GOOGLEFINANCE(A30,""closeyest""),"""")"),21900.0) -> 21900 | V30: =IFERROR(__xludf.DUMMYFUNCTION("IFERROR(GOOGLEFINANCE(A30,""changepct""),"""")"),0.46) -> 0.46 | W30: =IFERROR(__xludf.DUMMYFUNCTION("IFERROR(GOOGLEFINANCE(A30,""priceopen""),"""")"),21900.0) -> 21900 | X30: =IFERROR(__xludf.DUMMYFUNCTION("IFERROR(GOOGLEFINANCE(A30,""high""),"""")"),22050.0) -> 22050 | Y30: =IFERROR(__xludf.DUMMYFUNCTION("IFERROR(GOOGLEFINANCE(A30,""low""),"""")"),21650.0) -> 21650 | Z30: =IFERROR(__xludf.DUMMYFUNCTION("IFERROR(GOOGLEFINANCE(A30,""volume""),"""")"),34900.0) -> 34900 | AA30: =VLOOKUP(A30,Metrik!$C$2:$Y$959,5,0) -> Beverages | AB30: =VLOOKUP(A30,Metrik!$C$2:$Y$959,3,0) -> Consumer Non-Cyclicals
A31: ADHI | B31: {=VLOOKUP(A31,{Metrik!$C$2:$C$998,Metrik!$B$2:$B$998},2,0)} -> PT Adhi Karya (Persero) Tbk. | C31: =IFERROR(__xludf.DUMMYFUNCTION("GOOGLEFINANCE(""IDX:""&A31,""price"")"),158.0) -> 158 | D31: =IFERROR(__xludf.DUMMYFUNCTION("IF(A31="""","""", SPARKLINE( INDEX( GOOGLEFINANCE(""IDX:""&A31,""close"",TODAY()-365,TODAY()), ,2 ), {""linewidth"",1} )) "),"#N/A") -> #N/A | E31: IDXBUMN20 | F31: 4 Agustus 2026 | G31: =COUNTIFS($B$2:$B$1937,B31,$E$2:$E$1937,"<>") -> 1 | H31: =VLOOKUP(A31,Metrik!$C$2:$Y$959,8,0) -> -0.27 | I31: =VLOOKUP(A31,Metrik!$C$2:$Y$959,9,0) -> 0.41 | J31: =VLOOKUP(A31,Metrik!$C$2:$Y$959,10,0) -> -150 | K31: =VLOOKUP(A31,Metrik!$C$2:$Y$959,11,0) -> -18.7 | L31: =VLOOKUP(A31,Metrik!$C$2:$Y$959,12,0) -> 7.1 | M31: =VLOOKUP(A31,Metrik!$C$2:$Y$959,19,0) -> -320 | U31: =IFERROR(__xludf.DUMMYFUNCTION("IFERROR(GOOGLEFINANCE(A31,""closeyest""),"""")"),0.19) -> 0.19 | V31: =IFERROR(__xludf.DUMMYFUNCTION("IFERROR(GOOGLEFINANCE(A31,""changepct""),"""")"),-10.53) -> -10.53 | W31: =IFERROR(__xludf.DUMMYFUNCTION("IFERROR(GOOGLEFINANCE(A31,""priceopen""),"""")"),0.17) -> 0.17 | X31: =IFERROR(__xludf.DUMMYFUNCTION("IFERROR(GOOGLEFINANCE(A31,""high""),"""")"),0.17) -> 0.17 | Y31: =IFERROR(__xludf.DUMMYFUNCTION("IFERROR(GOOGLEFINANCE(A31,""low""),"""")"),0.17) -> 0.17 | Z31: =IFERROR(__xludf.DUMMYFUNCTION("IFERROR(GOOGLEFINANCE(A31,""volume""),"""")"),427.0) -> 427 | AA31: =VLOOKUP(A31,Metrik!$C$2:$Y$959,5,0) -> Heavy Constructions & Civil Engineering | AB31: =VLOOKUP(A31,Metrik!$C$2:$Y$959,3,0) -> Infrastructures
A32: ADMF | B32: {=VLOOKUP(A32,{Metrik!$C$2:$C$998,Metrik!$B$2:$B$998},2,0)} -> Adira Dinamika Multi Finance Tbk. | C32: =IFERROR(__xludf.DUMMYFUNCTION("GOOGLEFINANCE(""IDX:""&A32,""price"")"),8200.0) -> 8200 | D32: =IFERROR(__xludf.DUMMYFUNCTION("IF(A32="""","""", SPARKLINE( INDEX( GOOGLEFINANCE(""IDX:""&A32,""close"",TODAY()-365,TODAY()), ,2 ), {""linewidth"",1} )) "),"#N/A") -> #N/A | G32: =COUNTIFS($B$2:$B$1937,B32,$E$2:$E$1937,"<>") -> 0 | H32: =VLOOKUP(A32,Metrik!$C$2:$Y$959,8,0) -> 5.9 | I32: =VLOOKUP(A32,Metrik!$C$2:$Y$959,9,0) -> 0.66 | J32: =VLOOKUP(A32,Metrik!$C$2:$Y$959,10,0) -> 11.2 | K32: =VLOOKUP(A32,Metrik!$C$2:$Y$959,11,0) -> 4.4 | L32: =VLOOKUP(A32,Metrik!$C$2:$Y$959,12,0) -> 1.6 | M32: =VLOOKUP(A32,Metrik!$C$2:$Y$959,19,0) -> 64.1 | U32: =IFERROR(__xludf.DUMMYFUNCTION("IFERROR(GOOGLEFINANCE(A32,""closeyest""),"""")"),8050.0) -> 8050 | V32: =IFERROR(__xludf.DUMMYFUNCTION("IFERROR(GOOGLEFINANCE(A32,""changepct""),"""")"),1.86) -> 1.86 | W32: =IFERROR(__xludf.DUMMYFUNCTION("IFERROR(GOOGLEFINANCE(A32,""priceopen""),"""")"),8100.0) -> 8100 | X32: =IFERROR(__xludf.DUMMYFUNCTION("IFERROR(GOOGLEFINANCE(A32,""high""),"""")"),8300.0) -> 8300 | Y32: =IFERROR(__xludf.DUMMYFUNCTION("IFERROR(GOOGLEFINANCE(A32,""low""),"""")"),8050.0) -> 8050 | Z32: =IFERROR(__xludf.DUMMYFUNCTION("IFERROR(GOOGLEFINANCE(A32,""volume""),"""")"),48500.0) -> 48500 | AA32: =VLOOKUP(A32,Metrik!$C$2:$Y$959,5,0) -> Consumer Financing | AB32: =VLOOKUP(A32,Metrik!$C$2:$Y$959,3,0) -> Financials
A33: ADMG | B33: {=VLOOKUP(A33,{Metrik!$C$2:$C$998,Metrik!$B$2:$B$998},2,0)} -> Polychem Indonesia Tbk | C33: =IFERROR(__xludf.DUMMYFUNCTION("GOOGLEFINANCE(""IDX:""&A33,""price"")"),200.0) -> 200 | D33: =IFERROR(__xludf.DUMMYFUNCTION("IF(A33="""","""", SPARKLINE( INDEX( GOOGLEFINANCE(""IDX:""&A33,""close"",TODAY()-365,TODAY()), ,2 ), {""linewidth"",1} )) "),"#N/A") -> #N/A | G33: =COUNTIFS($B$2:$B$1937,B33,$E$2:$E$1937,"<>") -> 0 | H33: =VLOOKUP(A33,Metrik!$C$2:$Y$959,8,0) -> -250 | I33: =VLOOKUP(A33,Metrik!$C$2:$Y$959,9,0) -> 0.43 | J33: =VLOOKUP(A33,Metrik!$C$2:$Y$959,10,0) -> -0.17 | K33: =VLOOKUP(A33,Metrik!$C$2:$Y$959,11,0) -> -0.13 | L33: =VLOOKUP(A33,Metrik!$C$2:$Y$959,12,0) -> 0.37 | M33: =VLOOKUP(A33,Metrik!$C$2:$Y$959,19,0) -> -0.61 | U33: =IFERROR(__xludf.DUMMYFUNCTION("IFERROR(GOOGLEFINANCE(A33,""closeyest""),"""")"),0.12) -> 0.12 | V33: =IFERROR(__xludf.DUMMYFUNCTION("IFERROR(GOOGLEFINANCE(A33,""changepct""),"""")"),0.0) -> 0 | W33: =IFERROR(__xludf.DUMMYFUNCTION("IFERROR(GOOGLEFINANCE(A33,""priceopen""),"""")"),"") | X33: =IFERROR(__xludf.DUMMYFUNCTION("IFERROR(GOOGLEFINANCE(A33,""high""),"""")"),"") | Y33: =IFERROR(__xludf.DUMMYFUNCTION("IFERROR(GOOGLEFINANCE(A33,""low""),"""")"),"") | Z33: =IFERROR(__xludf.DUMMYFUNCTION("IFERROR(GOOGLEFINANCE(A33,""volume""),"""")"),0.0) -> 0 | AA33: =VLOOKUP(A33,Metrik!$C$2:$Y$959,5,0) -> Chemicals | AB33: =VLOOKUP(A33,Metrik!$C$2:$Y$959,3,0) -> Basic Materials
A34: ADMR | B34: {=VLOOKUP(A34,{Metrik!$C$2:$C$998,Metrik!$B$2:$B$998},2,0)} -> Alamtri Minerals Indonesia Tbk. | C34: =IFERROR(__xludf.DUMMYFUNCTION("GOOGLEFINANCE(""IDX:""&A34,""price"")"),1575.0) -> 1575 | D34: =IFERROR(__xludf.DUMMYFUNCTION("IF(A34="""","""", SPARKLINE( INDEX( GOOGLEFINANCE(""IDX:""&A34,""close"",TODAY()-365,TODAY()), ,2 ), {""linewidth"",1} )) "),"#N/A") -> #N/A | E34: IDXQ30 | F34: 4 Agustus 2026 | G34: =COUNTIFS($B$2:$B$1937,B34,$E$2:$E$1937,"<>") -> 9 | H34: =VLOOKUP(A34,Metrik!$C$2:$Y$959,8,0) -> 12.6 | I34: =VLOOKUP(A34,Metrik!$C$2:$Y$959,9,0) -> 2 | J34: =VLOOKUP(A34,Metrik!$C$2:$Y$959,10,0) -> 16.2 | K34: =VLOOKUP(A34,Metrik!$C$2:$Y$959,11,0) -> 9.1 | L34: =VLOOKUP(A34,Metrik!$C$2:$Y$959,12,0) -> 0.78 | M34: =VLOOKUP(A34,Metrik!$C$2:$Y$959,19,0) -> 110 | U34: =IFERROR(__xludf.DUMMYFUNCTION("IFERROR(GOOGLEFINANCE(A34,""closeyest""),"""")"),1465.0) -> 1465 | V34: =IFERROR(__xludf.DUMMYFUNCTION("IFERROR(GOOGLEFINANCE(A34,""changepct""),"""")"),7.51) -> 7.51 | W34: =IFERROR(__xludf.DUMMYFUNCTION("IFERROR(GOOGLEFINANCE(A34,""priceopen""),"""")"),1495.0) -> 1495 | X34: =IFERROR(__xludf.DUMMYFUNCTION("IFERROR(GOOGLEFINANCE(A34,""high""),"""")"),1640.0) -> 1640 | Y34: =IFERROR(__xludf.DUMMYFUNCTION("IFERROR(GOOGLEFINANCE(A34,""low""),"""")"),1485.0) -> 1485 | Z34: =IFERROR(__xludf.DUMMYFUNCTION("IFERROR(GOOGLEFINANCE(A34,""volume""),"""")"),4.32668E7) -> 43266800 | AA34: =VLOOKUP(A34,Metrik!$C$2:$Y$959,5,0) -> Coal | AB34: =VLOOKUP(A34,Metrik!$C$2:$Y$959,3,0) -> Energy
A35: ADMR | B35: {=VLOOKUP(A35,{Metrik!$C$2:$C$998,Metrik!$B$2:$B$998},2,0)} -> Alamtri Minerals Indonesia Tbk. | C35: =IFERROR(__xludf.DUMMYFUNCTION("GOOGLEFINANCE(""IDX:""&A35,""price"")"),1575.0) -> 1575 | D35: =IFERROR(__xludf.DUMMYFUNCTION("IF(A35="""","""", SPARKLINE( INDEX( GOOGLEFINANCE(""IDX:""&A35,""close"",TODAY()-365,TODAY()), ,2 ), {""linewidth"",1} )) "),"#N/A") -> #N/A | E35: Kompas100 | F35: 31 Juli 2026 | G35: =COUNTIFS($B$2:$B$1937,B35,$E$2:$E$1937,"<>") -> 9 | H35: =VLOOKUP(A35,Metrik!$C$2:$Y$959,8,0) -> 12.6 | I35: =VLOOKUP(A35,Metrik!$C$2:$Y$959,9,0) -> 2 | J35: =VLOOKUP(A35,Metrik!$C$2:$Y$959,10,0) -> 16.2 | K35: =VLOOKUP(A35,Metrik!$C$2:$Y$959,11,0) -> 9.1 | L35: =VLOOKUP(A35,Metrik!$C$2:$Y$959,12,0) -> 0.78 | M35: =VLOOKUP(A35,Metrik!$C$2:$Y$959,19,0) -> 110 | U35: =IFERROR(__xludf.DUMMYFUNCTION("IFERROR(GOOGLEFINANCE(A35,""closeyest""),"""")"),1465.0) -> 1465 | V35: =IFERROR(__xludf.DUMMYFUNCTION("IFERROR(GOOGLEFINANCE(A35,""changepct""),"""")"),7.51) -> 7.51 | W35: =IFERROR(__xludf.DUMMYFUNCTION("IFERROR(GOOGLEFINANCE(A35,""priceopen""),"""")"),1495.0) -> 1495 | X35: =IFERROR(__xludf.DUMMYFUNCTION("IFERROR(GOOGLEFINANCE(A35,""high""),"""")"),1640.0) -> 1640 | Y35: =IFERROR(__xludf.DUMMYFUNCTION("IFERROR(GOOGLEFINANCE(A35,""low""),"""")"),1485.0) -> 1485 | Z35: =IFERROR(__xludf.DUMMYFUNCTION("IFERROR(GOOGLEFINANCE(A35,""volume""),"""")"),4.32668E7) -> 43266800 | AA35: =VLOOKUP(A35,Metrik!$C$2:$Y$959,5,0) -> Coal | AB35: =VLOOKUP(A35,Metrik!$C$2:$Y$959,3,0) -> Energy
A36: ADMR | B36: {=VLOOKUP(A36,{Metrik!$C$2:$C$998,Metrik!$B$2:$B$998},2,0)} -> Alamtri Minerals Indonesia Tbk. | C36: =IFERROR(__xludf.DUMMYFUNCTION("GOOGLEFINANCE(""IDX:""&A36,""price"")"),1575.0) -> 1575 | D36: =IFERROR(__xludf.DUMMYFUNCTION("IF(A36="""","""", SPARKLINE( INDEX( GOOGLEFINANCE(""IDX:""&A36,""close"",TODAY()-365,TODAY()), ,2 ), {""linewidth"",1} )) "),"#N/A") -> #N/A | E36: LQ45 | F36: 31 Juli 2026 | G36: =COUNTIFS($B$2:$B$1937,B36,$E$2:$E$1937,"<>") -> 9 | H36: =VLOOKUP(A36,Metrik!$C$2:$Y$959,8,0) -> 12.6 | I36: =VLOOKUP(A36,Metrik!$C$2:$Y$959,9,0) -> 2 | J36: =VLOOKUP(A36,Metrik!$C$2:$Y$959,10,0) -> 16.2 | K36: =VLOOKUP(A36,Metrik!$C$2:$Y$959,11,0) -> 9.1 | L36: =VLOOKUP(A36,Metrik!$C$2:$Y$959,12,0) -> 0.78 | M36: =VLOOKUP(A36,Metrik!$C$2:$Y$959,19,0) -> 110 | U36: =IFERROR(__xludf.DUMMYFUNCTION("IFERROR(GOOGLEFINANCE(A36,""closeyest""),"""")"),1465.0) -> 1465 | V36: =IFERROR(__xludf.DUMMYFUNCTION("IFERROR(GOOGLEFINANCE(A36,""changepct""),"""")"),7.51) -> 7.51 | W36: =IFERROR(__xludf.DUMMYFUNCTION("IFERROR(GOOGLEFINANCE(A36,""priceopen""),"""")"),1495.0) -> 1495 | X36: =IFERROR(__xludf.DUMMYFUNCTION("IFERROR(GOOGLEFINANCE(A36,""high""),"""")"),1640.0) -> 1640 | Y36: =IFERROR(__xludf.DUMMYFUNCTION("IFERROR(GOOGLEFINANCE(A36,""low""),"""")"),1485.0) -> 1485 | Z36: =IFERROR(__xludf.DUMMYFUNCTION("IFERROR(GOOGLEFINANCE(A36,""volume""),"""")"),4.32668E7) -> 43266800 | AA36: =VLOOKUP(A36,Metrik!$C$2:$Y$959,5,0) -> Coal | AB36: =VLOOKUP(A36,Metrik!$C$2:$Y$959,3,0) -> Energy
A37: ADMR | B37: {=VLOOKUP(A37,{Metrik!$C$2:$C$998,Metrik!$B$2:$B$998},2,0)} -> Alamtri Minerals Indonesia Tbk. | C37: =IFERROR(__xludf.DUMMYFUNCTION("GOOGLEFINANCE(""IDX:""&A37,""price"")"),1575.0) -> 1575 | D37: =IFERROR(__xludf.DUMMYFUNCTION("IF(A37="""","""", SPARKLINE( INDEX( GOOGLEFINANCE(""IDX:""&A37,""close"",TODAY()-365,TODAY()), ,2 ), {""linewidth"",1} )) "),"#N/A") -> #N/A | E37: IDX80 | F37: 31 Juli 2026 | G37: =COUNTIFS($B$2:$B$1937,B37,$E$2:$E$1937,"<>") -> 9 | H37: =VLOOKUP(A37,Metrik!$C$2:$Y$959,8,0) -> 12.6 | I37: =VLOOKUP(A37,Metrik!$C$2:$Y$959,9,0) -> 2 | J37: =VLOOKUP(A37,Metrik!$C$2:$Y$959,10,0) -> 16.2 | K37: =VLOOKUP(A37,Metrik!$C$2:$Y$959,11,0) -> 9.1 | L37: =VLOOKUP(A37,Metrik!$C$2:$Y$959,12,0) -> 0.78 | M37: =VLOOKUP(A37,Metrik!$C$2:$Y$959,19,0) -> 110 | U37: =IFERROR(__xludf.DUMMYFUNCTION("IFERROR(GOOGLEFINANCE(A37,""closeyest""),"""")"),1465.0) -> 1465 | V37: =IFERROR(__xludf.DUMMYFUNCTION("IFERROR(GOOGLEFINANCE(A37,""changepct""),"""")"),7.51) -> 7.51 | W37: =IFERROR(__xludf.DUMMYFUNCTION("IFERROR(GOOGLEFINANCE(A37,""priceopen""),"""")"),1495.0) -> 1495 | X37: =IFERROR(__xludf.DUMMYFUNCTION("IFERROR(GOOGLEFINANCE(A37,""high""),"""")"),1640.0) -> 1640 | Y37: =IFERROR(__xludf.DUMMYFUNCTION("IFERROR(GOOGLEFINANCE(A37,""low""),"""")"),1485.0) -> 1485 | Z37: =IFERROR(__xludf.DUMMYFUNCTION("IFERROR(GOOGLEFINANCE(A37,""volume""),"""")"),4.32668E7) -> 43266800 | AA37: =VLOOKUP(A37,Metrik!$C$2:$Y$959,5,0) -> Coal | AB37: =VLOOKUP(A37,Metrik!$C$2:$Y$959,3,0) -> Energy
A38: ADMR | B38: {=VLOOKUP(A38,{Metrik!$C$2:$C$998,Metrik!$B$2:$B$998},2,0)} -> Alamtri Minerals Indonesia Tbk. | C38: =IFERROR(__xludf.DUMMYFUNCTION("GOOGLEFINANCE(""IDX:""&A38,""price"")"),1575.0) -> 1575 | D38: =IFERROR(__xludf.DUMMYFUNCTION("IF(A38="""","""", SPARKLINE( INDEX( GOOGLEFINANCE(""IDX:""&A38,""close"",TODAY()-365,TODAY()), ,2 ), {""linewidth"",1} )) "),"#N/A") -> #N/A | E38: IDX30 | F38: 31 Juli 2026 | G38: =COUNTIFS($B$2:$B$1937,B38,$E$2:$E$1937,"<>") -> 9 | H38: =VLOOKUP(A38,Metrik!$C$2:$Y$959,8,0) -> 12.6 | I38: =VLOOKUP(A38,Metrik!$C$2:$Y$959,9,0) -> 2 | J38: =VLOOKUP(A38,Metrik!$C$2:$Y$959,10,0) -> 16.2 | K38: =VLOOKUP(A38,Metrik!$C$2:$Y$959,11,0) -> 9.1 | L38: =VLOOKUP(A38,Metrik!$C$2:$Y$959,12,0) -> 0.78 | M38: =VLOOKUP(A38,Metrik!$C$2:$Y$959,19,0) -> 110 | U38: =IFERROR(__xludf.DUMMYFUNCTION("IFERROR(GOOGLEFINANCE(A38,""closeyest""),"""")"),1465.0) -> 1465 | V38: =IFERROR(__xludf.DUMMYFUNCTION("IFERROR(GOOGLEFINANCE(A38,""changepct""),"""")"),7.51) -> 7.51 | W38: =IFERROR(__xludf.DUMMYFUNCTION("IFERROR(GOOGLEFINANCE(A38,""priceopen""),"""")"),1495.0) -> 1495 | X38: =IFERROR(__xludf.DUMMYFUNCTION("IFERROR(GOOGLEFINANCE(A38,""high""),"""")"),1640.0) -> 1640 | Y38: =IFERROR(__xludf.DUMMYFUNCTION("IFERROR(GOOGLEFINANCE(A38,""low""),"""")"),1485.0) -> 1485 | Z38: =IFERROR(__xludf.DUMMYFUNCTION("IFERROR(GOOGLEFINANCE(A38,""volume""),"""")"),4.32668E7) -> 43266800 | AA38: =VLOOKUP(A38,Metrik!$C$2:$Y$959,5,0) -> Coal | AB38: =VLOOKUP(A38,Metrik!$C$2:$Y$959,3,0) -> Energy
A39: ADMR | B39: {=VLOOKUP(A39,{Metrik!$C$2:$C$998,Metrik!$B$2:$B$998},2,0)} -> Alamtri Minerals Indonesia Tbk. | C39: =IFERROR(__xludf.DUMMYFUNCTION("GOOGLEFINANCE(""IDX:""&A39,""price"")"),1575.0) -> 1575 | D39: =IFERROR(__xludf.DUMMYFUNCTION("IF(A39="""","""", SPARKLINE( INDEX( GOOGLEFINANCE(""IDX:""&A39,""close"",TODAY()-365,TODAY()), ,2 ), {""linewidth"",1} )) "),"#N/A") -> #N/A | E39: IDXSHAGROW | F39: 46356 | G39: =COUNTIFS($B$2:$B$1937,B39,$E$2:$E$1937,"<>") -> 9 | H39: =VLOOKUP(A39,Metrik!$C$2:$Y$959,8,0) -> 12.6 | I39: =VLOOKUP(A39,Metrik!$C$2:$Y$959,9,0) -> 2 | J39: =VLOOKUP(A39,Metrik!$C$2:$Y$959,10,0) -> 16.2 | K39: =VLOOKUP(A39,Metrik!$C$2:$Y$959,11,0) -> 9.1 | L39: =VLOOKUP(A39,Metrik!$C$2:$Y$959,12,0) -> 0.78 | M39: =VLOOKUP(A39,Metrik!$C$2:$Y$959,19,0) -> 110 | U39: =IFERROR(__xludf.DUMMYFUNCTION("IFERROR(GOOGLEFINANCE(A39,""closeyest""),"""")"),1465.0) -> 1465 | V39: =IFERROR(__xludf.DUMMYFUNCTION("IFERROR(GOOGLEFINANCE(A39,""changepct""),"""")"),7.51) -> 7.51 | W39: =IFERROR(__xludf.DUMMYFUNCTION("IFERROR(GOOGLEFINANCE(A39,""priceopen""),"""")"),1495.0) -> 1495 | X39: =IFERROR(__xludf.DUMMYFUNCTION("IFERROR(GOOGLEFINANCE(A39,""high""),"""")"),1640.0) -> 1640 | Y39: =IFERROR(__xludf.DUMMYFUNCTION("IFERROR(GOOGLEFINANCE(A39,""low""),"""")"),1485.0) -> 1485 | Z39: =IFERROR(__xludf.DUMMYFUNCTION("IFERROR(GOOGLEFINANCE(A39,""volume""),"""")"),4.32668E7) -> 43266800 | AA39: =VLOOKUP(A39,Metrik!$C$2:$Y$959,5,0) -> Coal | AB39: =VLOOKUP(A39,Metrik!$C$2:$Y$959,3,0) -> Energy
A40: ADMR | B40: {=VLOOKUP(A40,{Metrik!$C$2:$C$998,Metrik!$B$2:$B$998},2,0)} -> Alamtri Minerals Indonesia Tbk. | C40: =IFERROR(__xludf.DUMMYFUNCTION("GOOGLEFINANCE(""IDX:""&A40,""price"")"),1575.0) -> 1575 | D40: =IFERROR(__xludf.DUMMYFUNCTION("IF(A40="""","""", SPARKLINE( INDEX( GOOGLEFINANCE(""IDX:""&A40,""close"",TODAY()-365,TODAY()), ,2 ), {""linewidth"",1} )) "),"#N/A") -> #N/A | E40: Investor33 | F40: 46356 | G40: =COUNTIFS($B$2:$B$1937,B40,$E$2:$E$1937,"<>") -> 9 | H40: =VLOOKUP(A40,Metrik!$C$2:$Y$959,8,0) -> 12.6 | I40: =VLOOKUP(A40,Metrik!$C$2:$Y$959,9,0) -> 2 | J40: =VLOOKUP(A40,Metrik!$C$2:$Y$959,10,0) -> 16.2 | K40: =VLOOKUP(A40,Metrik!$C$2:$Y$959,11,0) -> 9.1 | L40: =VLOOKUP(A40,Metrik!$C$2:$Y$959,12,0) -> 0.78 | M40: =VLOOKUP(A40,Metrik!$C$2:$Y$959,19,0) -> 110 | U40: =IFERROR(__xludf.DUMMYFUNCTION("IFERROR(GOOGLEFINANCE(A40,""closeyest""),"""")"),1465.0) -> 1465 | V40: =IFERROR(__xludf.DUMMYFUNCTION("IFERROR(GOOGLEFINANCE(A40,""changepct""),"""")"),7.51) -> 7.51 | W40: =IFERROR(__xludf.DUMMYFUNCTION("IFERROR(GOOGLEFINANCE(A40,""priceopen""),"""")"),1495.0) -> 1495 | X40: =IFERROR(__xludf.DUMMYFUNCTION("IFERROR(GOOGLEFINANCE(A40,""high""),"""")"),1640.0) -> 1640 | Y40: =IFERROR(__xludf.DUMMYFUNCTION("IFERROR(GOOGLEFINANCE(A40,""low""),"""")"),1485.0) -> 1485 | Z40: =IFERROR(__xludf.DUMMYFUNCTION("IFERROR(GOOGLEFINANCE(A40,""volume""),"""")"),4.32668E7) -> 43266800 | AA40: =VLOOKUP(A40,Metrik!$C$2:$Y$959,5,0) -> Coal | AB40: =VLOOKUP(A40,Metrik!$C$2:$Y$959,3,0) -> Energy
...

Sheet NonBank
A1: Kode | B1: Nama Perusahaan | C1: Penutupan | D1: =IFERROR(__xludf.DUMMYFUNCTION("""Last Update: "" & TEXT(NOW() - GOOGLEFINANCE(""IDX:BBCA"",""datadelay"")/1440, ""dddd, yyyymmdd HH:mm"")"),"Last Update: Minggu, 20260614 14:19") -> Last Update: Minggu, 20260614 14:19 | E1: Index | F1: Index Expired | G1: ∑i ≥ 7 | H1: PER ≤ 15 | I1: PBV ≤ 3 | J1: ROE ≥ 12% | K1: ROA ≥ 7% | L1: DER ≤ 1.5 | M1: NPM ≥ 7% | N1: NIM ≥ 5% | O1: CAR ≥ 16% | P1: LDR 85-92% | Q1: NPL ≤ 2% | R1: BOPO ≤ 75% | S1: CIR ≤ 50% | T1: LAR ≤ 8% | U1: Sebelumnya | V1: %Change | W1: Open | X1: High | Y1: Low | Z1: Volume | AA1: Industry | AB1: Sektor
